Workbook
Name lstCategorias: Configurações!$B$5:$B$57
Name lstEstado: Configurações!$F$5:$F$8
Name lstEstoque: Configurações!$L$5:$L$6
Name lstTipos: Configurações!$I$5:$I$15

Sheet Dashboard
B2: BTG PACTUAL · INVENTÁRIO CONSOLIDADO · DASHBOARD
B3: Atualizado automaticamente · dados puxados das abas Catálogo e Movimentações
B5: PRODUTOS | E5: PEÇAS EM ESTOQUE | H5: CUSTO TOTAL DO ESTOQUE | K5: AD VALOREM MENSAL (0,50%)
B6: =Catálogo!B6 -> 600 | E6: =Catálogo!D6 -> 13596 | H6: =Catálogo!G6 -> 0 | K6: =H6*0.005 -> 0
B7: códigos únicos da cliente | E7: soma do saldo atual | H7: Qtde × Preço de Custo | K7: 0,50% sobre custo total
B10: RESUMO POR CATEGORIA
B11: CATEGORIA | C11: PRODUTOS | D11: PEÇAS | E11: CUSTO TOTAL | F11: % ESTOQUE | G11: % CUSTO
B12: VESTUÁRIO | C12: =COUNTIF(Catalogo[GRUPO],B12) -> 457 | D12: =SUMIFS(Catalogo[ESTOQUE BTG],Catalogo[GRUPO],B12) -> 6855 | E12: =SUMIFS(Catalogo[CUSTO TOTAL],Catalogo[GRUPO],B12) -> 0 | F12: =IFERROR(D12/$E$6,0) -> 0.50419241 | G12: =IFERROR(E12/$H$6,0) -> 0
B13: BOLSAS E MALAS | C13: =COUNTIF(Catalogo[GRUPO],B13) -> 24 | D13: =SUMIFS(Catalogo[ESTOQUE BTG],Catalogo[GRUPO],B13) -> 2457 | E13: =SUMIFS(Catalogo[CUSTO TOTAL],Catalogo[GRUPO],B13) -> 0 | F13: =IFERROR(D13/$E$6,0) -> 0.18071492 | G13: =IFERROR(E13/$H$6,0) -> 0
B14: BEBIDAS E MESA | C14: =COUNTIF(Catalogo[GRUPO],B14) -> 19 | D14: =SUMIFS(Catalogo[ESTOQUE BTG],Catalogo[GRUPO],B14) -> 51 | E14: =SUMIFS(Catalogo[CUSTO TOTAL],Catalogo[GRUPO],B14) -> 0 | F14: =IFERROR(D14/$E$6,0) -> 0.0037511033 | G14: =IFERROR(E14/$H$6,0) -> 0
B15: ESCRITÓRIOS E PAPELARIA | C15: =COUNTIF(Catalogo[GRUPO],B15) -> 12 | D15: =SUMIFS(Catalogo[ESTOQUE BTG],Catalogo[GRUPO],B15) -> 257 | E15: =SUMIFS(Catalogo[CUSTO TOTAL],Catalogo[GRUPO],B15) -> 0 | F15: =IFERROR(D15/$E$6,0) -> 0.018902618 | G15: =IFERROR(E15/$H$6,0) -> 0
B16: ACESSÓRIOS | C16: =COUNTIF(Catalogo[GRUPO],B16) -> 15 | D16: =SUMIFS(Catalogo[ESTOQUE BTG],Catalogo[GRUPO],B16) -> 1483 | E16: =SUMIFS(Catalogo[CUSTO TOTAL],Catalogo[GRUPO],B16) -> 0 | F16: =IFERROR(D16/$E$6,0) -> 0.1090762 | G16: =IFERROR(E16/$H$6,0) -> 0
B17: MATERIAL DE EVENTO | C17: =COUNTIF(Catalogo[GRUPO],B17) -> 20 | D17: =SUMIFS(Catalogo[ESTOQUE BTG],Catalogo[GRUPO],B17) -> 201 | E17: =SUMIFS(Catalogo[CUSTO TOTAL],Catalogo[GRUPO],B17) -> 0 | F17: =IFERROR(D17/$E$6,0) -> 0.01478376 | G17: =IFERROR(E17/$H$6,0) -> 0
B18: TOTAL | C18: =SUM(C12:C17) -> 547 | D18: =SUM(D12:D17) -> 11304 | E18: =SUM(E12:E17) -> 0 | F18: =SUM(F12:F17) -> 0.83142101 | G18: =SUM(G12:G17) -> 0
B21: ÚLTIMAS 20 MOVIMENTAÇÕES
B22: DATA | C22: TIPO MOV. | D22: CÓD. SKU | E22: PRODUTO | F22: QTDE | G22: ESTOQUE | H22: RESPONSÁVEL
B23: =IFERROR(INDEX(Movimentações!$A$6:$A$4773,COUNTA(Movimentações!$C$6:$C$4773)-0),"") -> 0 | C23: =IFERROR(INDEX(Movimentações!$B$6:$B$4773,COUNTA(Movimentações!$C$6:$C$4773)-0),"") -> 0 | D23: =IFERROR(INDEX(Movimentações!$C$6:$C$4773,COUNTA(Movimentações!$C$6:$C$4773)-0),"") -> 0 | E23: =IFERROR(INDEX(Movimentações!$D$6:$D$4773,COUNTA(Movimentações!$C$6:$C$4773)-0),"") | F23: =IFERROR(INDEX(Movimentações!$E$6:$E$4773,COUNTA(Movimentações!$C$6:$C$4773)-0),"") -> 0 | G23: =IFERROR(INDEX(Movimentações!$G$6:$G$4773,COUNTA(Movimentações!$C$6:$C$4773)-0),"") -> 0 | H23: =IFERROR(INDEX(Movimentações!$K$6:$K$4773,COUNTA(Movimentações!$C$6:$C$4773)-0),"") -> 0
B24: =IFERROR(INDEX(Movimentações!$A$6:$A$4773,COUNTA(Movimentações!$C$6:$C$4773)-1),"") -> 0 | C24: =IFERROR(INDEX(Movimentações!$B$6:$B$4773,COUNTA(Movimentações!$C$6:$C$4773)-1),"") -> 0 | D24: =IFERROR(INDEX(Movimentações!$C$6:$C$4773,COUNTA(Movimentações!$C$6:$C$4773)-1),"") -> 0 | E24: =IFERROR(INDEX(Movimentações!$D$6:$D$4773,COUNTA(Movimentações!$C$6:$C$4773)-1),"") | F24: =IFERROR(INDEX(Movimentações!$E$6:$E$4773,COUNTA(Movimentações!$C$6:$C$4773)-1),"") -> 0 | G24: =IFERROR(INDEX(Movimentações!$G$6:$G$4773,COUNTA(Movimentações!$C$6:$C$4773)-1),"") -> 0 | H24: =IFERROR(INDEX(Movimentações!$K$6:$K$4773,COUNTA(Movimentações!$C$6:$C$4773)-1),"") -> 0
B25: =IFERROR(INDEX(Movimentações!$A$6:$A$4773,COUNTA(Movimentações!$C$6:$C$4773)-2),"") -> 0 | C25: =IFERROR(INDEX(Movimentações!$B$6:$B$4773,COUNTA(Movimentações!$C$6:$C$4773)-2),"") -> 0 | D25: =IFERROR(INDEX(Movimentações!$C$6:$C$4773,COUNTA(Movimentações!$C$6:$C$4773)-2),"") -> 0 | E25: =IFERROR(INDEX(Movimentações!$D$6:$D$4773,COUNTA(Movimentações!$C$6:$C$4773)-2),"") | F25: =IFERROR(INDEX(Movimentações!$E$6:$E$4773,COUNTA(Movimentações!$C$6:$C$4773)-2),"") -> 0 | G25: =IFERROR(INDEX(Movimentações!$G$6:$G$4773,COUNTA(Movimentações!$C$6:$C$4773)-2),"") -> 0 | H25: =IFERROR(INDEX(Movimentações!$K$6:$K$4773,COUNTA(Movimentações!$C$6:$C$4773)-2),"") -> 0
B26: =IFERROR(INDEX(Movimentações!$A$6:$A$4773,COUNTA(Movimentações!$C$6:$C$4773)-3),"") -> 0 | C26: =IFERROR(INDEX(Movimentações!$B$6:$B$4773,COUNTA(Movimentações!$C$6:$C$4773)-3),"") -> 0 | D26: =IFERROR(INDEX(Movimentações!$C$6:$C$4773,COUNTA(Movimentações!$C$6:$C$4773)-3),"") -> 0 | E26: =IFERROR(INDEX(Movimentações!$D$6:$D$4773,COUNTA(Movimentações!$C$6:$C$4773)-3),"") | F26: =IFERROR(INDEX(Movimentações!$E$6:$E$4773,COUNTA(Movimentações!$C$6:$C$4773)-3),"") -> 0 | G26: =IFERROR(INDEX(Movimentações!$G$6:$G$4773,COUNTA(Movimentações!$C$6:$C$4773)-3),"") -> 0 | H26: =IFERROR(INDEX(Movimentações!$K$6:$K$4773,COUNTA(Movimentações!$C$6:$C$4773)-3),"") -> 0
B27: =IFERROR(INDEX(Movimentações!$A$6:$A$4773,COUNTA(Movimentações!$C$6:$C$4773)-4),"") -> 0 | C27: =IFERROR(INDEX(Movimentações!$B$6:$B$4773,COUNTA(Movimentações!$C$6:$C$4773)-4),"") -> 0 | D27: =IFERROR(INDEX(Movimentações!$C$6:$C$4773,COUNTA(Movimentações!$C$6:$C$4773)-4),"") -> 0 | E27: =IFERROR(INDEX(Movimentações!$D$6:$D$4773,COUNTA(Movimentações!$C$6:$C$4773)-4),"") | F27: =IFERROR(INDEX(Movimentações!$E$6:$E$4773,COUNTA(Movimentações!$C$6:$C$4773)-4),"") -> 0 | G27: =IFERROR(INDEX(Movimentações!$G$6:$G$4773,COUNTA(Movimentações!$C$6:$C$4773)-4),"") -> 0 | H27: =IFERROR(INDEX(Movimentações!$K$6:$K$4773,COUNTA(Movimentações!$C$6:$C$4773)-4),"") -> 0
B28: =IFERROR(INDEX(Movimentações!$A$6:$A$4773,COUNTA(Movimentações!$C$6:$C$4773)-5),"") -> 0 | C28: =IFERROR(INDEX(Movimentações!$B$6:$B$4773,COUNTA(Movimentações!$C$6:$C$4773)-5),"") -> 0 | D28: =IFERROR(INDEX(Movimentações!$C$6:$C$4773,COUNTA(Movimentações!$C$6:$C$4773)-5),"") -> 0 | E28: =IFERROR(INDEX(Movimentações!$D$6:$D$4773,COUNTA(Movimentações!$C$6:$C$4773)-5),"") | F28: =IFERROR(INDEX(Movimentações!$E$6:$E$4773,COUNTA(Movimentações!$C$6:$C$4773)-5),"") -> 0 | G28: =IFERROR(INDEX(Movimentações!$G$6:$G$4773,COUNTA(Movimentações!$C$6:$C$4773)-5),"") -> 0 | H28: =IFERROR(INDEX(Movimentações!$K$6:$K$4773,COUNTA(Movimentações!$C$6:$C$4773)-5),"") -> 0
B29: =IFERROR(INDEX(Movimentações!$A$6:$A$4773,COUNTA(Movimentações!$C$6:$C$4773)-6),"") -> 0 | C29: =IFERROR(INDEX(Movimentações!$B$6:$B$4773,COUNTA(Movimentações!$C$6:$C$4773)-6),"") -> 0 | D29: =IFERROR(INDEX(Movimentações!$C$6:$C$4773,COUNTA(Movimentações!$C$6:$C$4773)-6),"") -> 0 | E29: =IFERROR(INDEX(Movimentações!$D$6:$D$4773,COUNTA(Movimentações!$C$6:$C$4773)-6),"") | F29: =IFERROR(INDEX(Movimentações!$E$6:$E$4773,COUNTA(Movimentações!$C$6:$C$4773)-6),"") -> 0 | G29: =IFERROR(INDEX(Movimentações!$G$6:$G$4773,COUNTA(Movimentações!$C$6:$C$4773)-6),"") -> 0 | H29: =IFERROR(INDEX(Movimentações!$K$6:$K$4773,COUNTA(Movimentações!$C$6:$C$4773)-6),"") -> 0
B30: =IFERROR(INDEX(Movimentações!$A$6:$A$4773,COUNTA(Movimentações!$C$6:$C$4773)-7),"") -> 0 | C30: =IFERROR(INDEX(Movimentações!$B$6:$B$4773,COUNTA(Movimentações!$C$6:$C$4773)-7),"") -> 0 | D30: =IFERROR(INDEX(Movimentações!$C$6:$C$4773,COUNTA(Movimentações!$C$6:$C$4773)-7),"") -> 0 | E30: =IFERROR(INDEX(Movimentações!$D$6:$D$4773,COUNTA(Movimentações!$C$6:$C$4773)-7),"") | F30: =IFERROR(INDEX(Movimentações!$E$6:$E$4773,COUNTA(Movimentações!$C$6:$C$4773)-7),"") -> 0 | G30: =IFERROR(INDEX(Movimentações!$G$6:$G$4773,COUNTA(Movimentações!$C$6:$C$4773)-7),"") -> 0 | H30: =IFERROR(INDEX(Movimentações!$K$6:$K$4773,COUNTA(Movimentações!$C$6:$C$4773)-7),"") -> 0
B31: =IFERROR(INDEX(Movimentações!$A$6:$A$4773,COUNTA(Movimentações!$C$6:$C$4773)-8),"") -> 0 | C31: =IFERROR(INDEX(Movimentações!$B$6:$B$4773,COUNTA(Movimentações!$C$6:$C$4773)-8),"") -> 0 | D31: =IFERROR(INDEX(Movimentações!$C$6:$C$4773,COUNTA(Movimentações!$C$6:$C$4773)-8),"") -> 0 | E31: =IFERROR(INDEX(Movimentações!$D$6:$D$4773,COUNTA(Movimentações!$C$6:$C$4773)-8),"") | F31: =IFERROR(INDEX(Movimentações!$E$6:$E$4773,COUNTA(Movimentações!$C$6:$C$4773)-8),"") -> 0 | G31: =IFERROR(INDEX(Movimentações!$G$6:$G$4773,COUNTA(Movimentações!$C$6:$C$4773)-8),"") -> 0 | H31: =IFERROR(INDEX(Movimentações!$K$6:$K$4773,COUNTA(Movimentações!$C$6:$C$4773)-8),"") -> 0
B32: =IFERROR(INDEX(Movimentações!$A$6:$A$4773,COUNTA(Movimentações!$C$6:$C$4773)-9),"") -> 46204 | C32: =IFERROR(INDEX(Movimentações!$B$6:$B$4773,COUNTA(Movimentações!$C$6:$C$4773)-9),"") -> ENTRADA | D32: =IFERROR(INDEX(Movimentações!$C$6:$C$4773,COUNTA(Movimentações!$C$6:$C$4773)-9),"") -> BTG-2210 | E32: =IFERROR(INDEX(Movimentações!$D$6:$D$4773,COUNTA(Movimentações!$C$6:$C$4773)-9),"") -> POLO PIQUET ARPOADOR MASC. | F32: =IFERROR(INDEX(Movimentações!$E$6:$E$4773,COUNTA(Movimentações!$C$6:$C$4773)-9),"") -> 2 | G32: =IFERROR(INDEX(Movimentações!$G$6:$G$4773,COUNTA(Movimentações!$C$6:$C$4773)-9),"") -> Store | H32: =IFERROR(INDEX(Movimentações!$K$6:$K$4773,COUNTA(Movimentações!$C$6:$C$4773)-9),"") -> RAFAEL
B33: =IFERROR(INDEX(Movimentações!$A$6:$A$4773,COUNTA(Movimentações!$C$6:$C$4773)-10),"") -> 46204 | C33: =IFERROR(INDEX(Movimentações!$B$6:$B$4773,COUNTA(Movimentações!$C$6:$C$4773)-10),"") -> ENTRADA | D33: =IFERROR(INDEX(Movimentações!$C$6:$C$4773,COUNTA(Movimentações!$C$6:$C$4773)-10),"") -> BTG-2209 | E33: =IFERROR(INDEX(Movimentações!$D$6:$D$4773,COUNTA(Movimentações!$C$6:$C$4773)-10),"") -> POLO PIQUET ARPOADOR MASC. | F33: =IFERROR(INDEX(Movimentações!$E$6:$E$4773,COUNTA(Movimentações!$C$6:$C$4773)-10),"") -> 1 | G33: =IFERROR(INDEX(Movimentações!$G$6:$G$4773,COUNTA(Movimentações!$C$6:$C$4773)-10),"") -> Store | H33: =IFERROR(INDEX(Movimentações!$K$6:$K$4773,COUNTA(Movimentações!$C$6:$C$4773)-10),"") -> RAFAEL
B34: =IFERROR(INDEX(Movimentações!$A$6:$A$4773,COUNTA(Movimentações!$C$6:$C$4773)-11),"") -> 46204 | C34: =IFERROR(INDEX(Movimentações!$B$6:$B$4773,COUNTA(Movimentações!$C$6:$C$4773)-11),"") -> ENTRADA | D34: =IFERROR(INDEX(Movimentações!$C$6:$C$4773,COUNTA(Movimentações!$C$6:$C$4773)-11),"") -> BTG-2208 | E34: =IFERROR(INDEX(Movimentações!$D$6:$D$4773,COUNTA(Movimentações!$C$6:$C$4773)-11),"") -> POLO PIQUET ARPOADOR MASC. | F34: =IFERROR(INDEX(Movimentações!$E$6:$E$4773,COUNTA(Movimentações!$C$6:$C$4773)-11),"") -> 7 | G34: =IFERROR(INDEX(Movimentações!$G$6:$G$4773,COUNTA(Movimentações!$C$6:$C$4773)-11),"") -> Store | H34: =IFERROR(INDEX(Movimentações!$K$6:$K$4773,COUNTA(Movimentações!$C$6:$C$4773)-11),"") -> RAFAEL
B35: =IFERROR(INDEX(Movimentações!$A$6:$A$4773,COUNTA(Movimentações!$C$6:$C$4773)-12),"") -> 46204 | C35: =IFERROR(INDEX(Movimentações!$B$6:$B$4773,COUNTA(Movimentações!$C$6:$C$4773)-12),"") -> ENTRADA | D35: =IFERROR(INDEX(Movimentações!$C$6:$C$4773,COUNTA(Movimentações!$C$6:$C$4773)-12),"") -> BTG-2213 | E35: =IFERROR(INDEX(Movimentações!$D$6:$D$4773,COUNTA(Movimentações!$C$6:$C$4773)-12),"") -> POLO PIQUET ARPOADOR MASC. | F35: =IFERROR(INDEX(Movimentações!$E$6:$E$4773,COUNTA(Movimentações!$C$6:$C$4773)-12),"") -> 68 | G35: =IFERROR(INDEX(Movimentações!$G$6:$G$4773,COUNTA(Movimentações!$C$6:$C$4773)-12),"") -> Store | H35: =IFERROR(INDEX(Movimentações!$K$6:$K$4773,COUNTA(Movimentações!$C$6:$C$4773)-12),"") -> RAFAEL
B36: =IFERROR(INDEX(Movimentações!$A$6:$A$4773,COUNTA(Movimentações!$C$6:$C$4773)-13),"") -> 46204 | C36: =IFERROR(INDEX(Movimentações!$B$6:$B$4773,COUNTA(Movimentações!$C$6:$C$4773)-13),"") -> ENTRADA | D36: =IFERROR(INDEX(Movimentações!$C$6:$C$4773,COUNTA(Movimentações!$C$6:$C$4773)-13),"") -> BTG-2212 | E36: =IFERROR(INDEX(Movimentações!$D$6:$D$4773,COUNTA(Movimentações!$C$6:$C$4773)-13),"") -> POLO PIQUET ARPOADOR MASC. | F36: =IFERROR(INDEX(Movimentações!$E$6:$E$4773,COUNTA(Movimentações!$C$6:$C$4773)-13),"") -> 1 | G36: =IFERROR(INDEX(Movimentações!$G$6:$G$4773,COUNTA(Movimentações!$C$6:$C$4773)-13),"") -> Store | H36: =IFERROR(INDEX(Movimentações!$K$6:$K$4773,COUNTA(Movimentações!$C$6:$C$4773)-13),"") -> RAFAEL
B37: =IFERROR(INDEX(Movimentações!$A$6:$A$4773,COUNTA(Movimentações!$C$6:$C$4773)-14),"") -> 46204 | C37: =IFERROR(INDEX(Movimentações!$B$6:$B$4773,COUNTA(Movimentações!$C$6:$C$4773)-14),"") -> ENTRADA | D37: =IFERROR(INDEX(Movimentações!$C$6:$C$4773,COUNTA(Movimentações!$C$6:$C$4773)-14),"") -> BTG-2211 | E37: =IFERROR(INDEX(Movimentações!$D$6:$D$4773,COUNTA(Movimentações!$C$6:$C$4773)-14),"") -> POLO PIQUET ARPOADOR MASC. | F37: =IFERROR(INDEX(Movimentações!$E$6:$E$4773,COUNTA(Movimentações!$C$6:$C$4773)-14),"") -> 50 | G37: =IFERROR(INDEX(Movimentações!$G$6:$G$4773,COUNTA(Movimentações!$C$6:$C$4773)-14),"") -> Store | H37: =IFERROR(INDEX(Movimentações!$K$6:$K$4773,COUNTA(Movimentações!$C$6:$C$4773)-14),"") -> RAFAEL
B38: =IFERROR(INDEX(Movimentações!$A$6:$A$4773,COUNTA(Movimentações!$C$6:$C$4773)-15),"") -> 46204 | C38: =IFERROR(INDEX(Movimentações!$B$6:$B$4773,COUNTA(Movimentações!$C$6:$C$4773)-15),"") -> ENTRADA | D38: =IFERROR(INDEX(Movimentações!$C$6:$C$4773,COUNTA(Movimentações!$C$6:$C$4773)-15),"") -> BTG-2212 | E38: =IFERROR(INDEX(Movimentações!$D$6:$D$4773,COUNTA(Movimentações!$C$6:$C$4773)-15),"") -> POLO PIQUET ARPOADOR MASC. | F38: =IFERROR(INDEX(Movimentações!$E$6:$E$4773,COUNTA(Movimentações!$C$6:$C$4773)-15),"") -> 17 | G38: =IFERROR(INDEX(Movimentações!$G$6:$G$4773,COUNTA(Movimentações!$C$6:$C$4773)-15),"") -> Store | H38: =IFERROR(INDEX(Movimentações!$K$6:$K$4773,COUNTA(Movimentações!$C$6:$C$4773)-15),"") -> RAFAEL
B39: =IFERROR(INDEX(Movimentações!$A$6:$A$4773,COUNTA(Movimentações!$C$6:$C$4773)-16),"") -> 46204 | C39: =IFERROR(INDEX(Movimentações!$B$6:$B$4773,COUNTA(Movimentações!$C$6:$C$4773)-16),"") -> ENTRADA | D39: =IFERROR(INDEX(Movimentações!$C$6:$C$4773,COUNTA(Movimentações!$C$6:$C$4773)-16),"") -> BTG-2211 | E39: =IFERROR(INDEX(Movimentações!$D$6:$D$4773,COUNTA(Movimentações!$C$6:$C$4773)-16),"") -> POLO PIQUET ARPOADOR MASC. | F39: =IFERROR(INDEX(Movimentações!$E$6:$E$4773,COUNTA(Movimentações!$C$6:$C$4773)-16),"") -> 18 | G39: =IFERROR(INDEX(Movimentações!$G$6:$G$4773,COUNTA(Movimentações!$C$6:$C$4773)-16),"") -> Store | H39: =IFERROR(INDEX(Movimentações!$K$6:$K$4773,COUNTA(Movimentações!$C$6:$C$4773)-16),"") -> RAFAEL
B40: =IFERROR(INDEX(Movimentações!$A$6:$A$4773,COUNTA(Movimentações!$C$6:$C$4773)-17),"") -> 46204 | C40: =IFERROR(INDEX(Movimentações!$B$6:$B$4773,COUNTA(Movimentações!$C$6:$C$4773)-17),"") -> ENTRADA | D40: =IFERROR(INDEX(Movimentações!$C$6:$C$4773,COUNTA(Movimentações!$C$6:$C$4773)-17),"") -> BTG-2210 | E40: =IFERROR(INDEX(Movimentações!$D$6:$D$4773,COUNTA(Movimentações!$C$6:$C$4773)-17),"") -> POLO PIQUET ARPOADOR MASC. | F40: =IFERROR(INDEX(Movimentações!$E$6:$E$4773,COUNTA(Movimentações!$C$6:$C$4773)-17),"") -> 60 | G40: =IFERROR(INDEX(Movimentações!$G$6:$G$4773,COUNTA(Movimentações!$C$6:$C$4773)-17),"") -> Store | H40: =IFERROR(INDEX(Movimentações!$K$6:$K$4773,COUNTA(Movimentações!$C$6:$C$4773)-17),"") -> RAFAEL
B41: =IFERROR(INDEX(Movimentações!$A$6:$A$4773,COUNTA(Movimentações!$C$6:$C$4773)-18),"") -> 46204 | C41: =IFERROR(INDEX(Movimentações!$B$6:$B$4773,COUNTA(Movimentações!$C$6:$C$4773)-18),"") -> ENTRADA | D41: =IFERROR(INDEX(Movimentações!$C$6:$C$4773,COUNTA(Movimentações!$C$6:$C$4773)-18),"") -> BTG-2210 | E41: =IFERROR(INDEX(Movimentações!$D$6:$D$4773,COUNTA(Movimentações!$C$6:$C$4773)-18),"") -> POLO PIQUET ARPOADOR MASC. | F41: =IFERROR(INDEX(Movimentações!$E$6:$E$4773,COUNTA(Movimentações!$C$6:$C$4773)-18),"") -> 24 | G41: =IFERROR(INDEX(Movimentações!$G$6:$G$4773,COUNTA(Movimentações!$C$6:$C$4773)-18),"") -> Store | H41: =IFERROR(INDEX(Movimentações!$K$6:$K$4773,COUNTA(Movimentações!$C$6:$C$4773)-18),"") -> RAFAEL
B42: =IFERROR(INDEX(Movimentações!$A$6:$A$4773,COUNTA(Movimentações!$C$6:$C$4773)-19),"") -> 46204 | C42: =IFERROR(INDEX(Movimentações!$B$6:$B$4773,COUNTA(Movimentações!$C$6:$C$4773)-19),"") -> ENTRADA | D42: =IFERROR(INDEX(Movimentações!$C$6:$C$4773,COUNTA(Movimentações!$C$6:$C$4773)-19),"") -> BTG-2208 | E42: =IFERROR(INDEX(Movimentações!$D$6:$D$4773,COUNTA(Movimentações!$C$6:$C$4773)-19),"") -> POLO PIQUET ARPOADOR MASC. | F42: =IFERROR(INDEX(Movimentações!$E$6:$E$4773,COUNTA(Movimentações!$C$6:$C$4773)-19),"") -> 60 | G42: =IFERROR(INDEX(Movimentações!$G$6:$G$4773,COUNTA(Movimentações!$C$6:$C$4773)-19),"") -> Store | H42: =IFERROR(INDEX(Movimentações!$K$6:$K$4773,COUNTA(Movimentações!$C$6:$C$4773)-19),"") -> RAFAEL

Sheet Catálogo
B2: BTG PACTUAL · CATÁLOGO · ESTOQUE BTG
B3: 1 linha por produto (código da cliente) · Estoque BTG consolidado · filtre por GRUPO ou CATEGORIA
B5: PRODUTOS | D5: PEÇAS EM ESTOQUE | G5: CUSTO TOTAL DO ESTOQUE
B6: =COUNTA(Catalogo[CÓD. CLIENTE]) -> 600 | D6: =SUM(Catalogo[ESTOQUE BTG]) -> 13596 | G6: =SUM(Catalogo[CUSTO TOTAL]) -> 0
A7: # | B7: CÓD. CLIENTE | C7: GÊNERO | D7: CATEGORIA | E7: GRUPO | F7: PRODUTO | G7: COR | H7: TAM | I7: PREÇO UNIT. | J7: ESTOQUE BTG | K7: CUSTO TOTAL | L7: # SKUs | M7: PEDIDO 1- entregar BTG (saida) | N7: PEDIDO 2 BTG entregar Dutelog (entrada) | O7: PEDIDO 3- applicato entregar duelog 12/06 | P7: PEDIDO 4- applicato entregar duelog 29/06 | Q7: PEDIDO 5- applicato entregar duelog 15/07 | R7: PEDIDO 6- applicato entregar duelog 20/07 | S7: PEDIDO 7- applicato entregar duelog 30/07 | T7: PEDIDO 8- applicato entregar duelog 01/11 | U7: QTD SOLIC. | V7: DISPONÍVEL
A8: 1 | B8: A.01.0782.001.P | C8: =IF(B8="","",IFERROR(IF(TRIM(MID(SUBSTITUTE(B8,".",REPT(" ",50)),51,50))="01","Masculino",IF(TRIM(MID(SUBSTITUTE(B8,".",REPT(" ",50)),51,50))="02","Feminino",IF(TRIM(MID(SUBSTITUTE(B8,".",REPT(" ",50)),51,50))="03","Outros","—"))),"—")) -> Masculino | D8: =IFERROR(INDEX(SKUs!$E$6:$E$1997,MATCH(B8,SKUs!$C$6:$C$1997,0)),"") -> POLO | E8: =IFERROR(VLOOKUP(D8,Configurações!$N$5:$O$46,2,FALSE()),"OUTROS") -> VESTUÁRIO | F8: =IFERROR(INDEX(SKUs!$F$6:$F$1997,MATCH(B8,SKUs!$C$6:$C$1997,0)),"") -> POLO COPA MASC. | G8: =IFERROR(INDEX(SKUs!$G$6:$G$1997,MATCH(B8,SKUs!$C$6:$C$1997,0)),"") -> AZUL | H8: =IFERROR(INDEX(SKUs!$H$6:$H$1997,MATCH(B8,SKUs!$C$6:$C$1997,0)),"") -> G | I8: =IFERROR(INDEX(SKUs!#REF!,MATCH(B8,SKUs!$C$6:$C$1997,0)),"") | J8: =SUMIFS(SKUs!$I$6:$I$1997,SKUs!$C$6:$C$1997,B8) -> 0 | K8: =IFERROR(I8*J8,0) -> 0 | L8: =COUNTIF(SKUs!$C$6:$C$1997,B8) -> 1 | U8: =SUM(M8:R8) -> 0 | V8: =IF(B8="","",J8) -> 0
A9: 2 | B9: A.01.0782.001.M | C9: =IF(B9="","",IFERROR(IF(TRIM(MID(SUBSTITUTE(B9,".",REPT(" ",50)),51,50))="01","Masculino",IF(TRIM(MID(SUBSTITUTE(B9,".",REPT(" ",50)),51,50))="02","Feminino",IF(TRIM(MID(SUBSTITUTE(B9,".",REPT(" ",50)),51,50))="03","Outros","—"))),"—")) -> Masculino | D9: =IFERROR(INDEX(SKUs!$E$6:$E$1997,MATCH(B9,SKUs!$C$6:$C$1997,0)),"") -> POLO | E9: =IFERROR(VLOOKUP(D9,Configurações!$N$5:$O$46,2,FALSE()),"OUTROS") -> VESTUÁRIO | F9: =IFERROR(INDEX(SKUs!$F$6:$F$1997,MATCH(B9,SKUs!$C$6:$C$1997,0)),"") -> POLO COPA MASC. | G9: =IFERROR(INDEX(SKUs!$G$6:$G$1997,MATCH(B9,SKUs!$C$6:$C$1997,0)),"") -> AZUL | H9: =IFERROR(INDEX(SKUs!$H$6:$H$1997,MATCH(B9,SKUs!$C$6:$C$1997,0)),"") -> M | I9: =IFERROR(INDEX(SKUs!#REF!,MATCH(B9,SKUs!$C$6:$C$1997,0)),"") | J9: =SUMIFS(SKUs!$I$6:$I$1997,SKUs!$C$6:$C$1997,B9) -> 0 | K9: =IFERROR(I9*J9,0) -> 0 | L9: =COUNTIF(SKUs!$C$6:$C$1997,B9) -> 1 | U9: =SUM(M9:R9) -> 0 | V9: =IF(B9="","",J9) -> 0
A10: 3 | B10: A.01.0782.001.G | C10: =IF(B10="","",IFERROR(IF(TRIM(MID(SUBSTITUTE(B10,".",REPT(" ",50)),51,50))="01","Masculino",IF(TRIM(MID(SUBSTITUTE(B10,".",REPT(" ",50)),51,50))="02","Feminino",IF(TRIM(MID(SUBSTITUTE(B10,".",REPT(" ",50)),51,50))="03","Outros","—"))),"—")) -> Masculino | D10: =IFERROR(INDEX(SKUs!$E$6:$E$1997,MATCH(B10,SKUs!$C$6:$C$1997,0)),"") -> POLO | E10: =IFERROR(VLOOKUP(D10,Configurações!$N$5:$O$46,2,FALSE()),"OUTROS") -> VESTUÁRIO | F10: =IFERROR(INDEX(SKUs!$F$6:$F$1997,MATCH(B10,SKUs!$C$6:$C$1997,0)),"") -> POLO COPA MASC. | G10: =IFERROR(INDEX(SKUs!$G$6:$G$1997,MATCH(B10,SKUs!$C$6:$C$1997,0)),"") -> AZUL | H10: =IFERROR(INDEX(SKUs!$H$6:$H$1997,MATCH(B10,SKUs!$C$6:$C$1997,0)),"") -> XG | I10: =IFERROR(INDEX(SKUs!#REF!,MATCH(B10,SKUs!$C$6:$C$1997,0)),"") | J10: =SUMIFS(SKUs!$I$6:$I$1997,SKUs!$C$6:$C$1997,B10) -> 0 | K10: =IFERROR(I10*J10,0) -> 0 | L10: =COUNTIF(SKUs!$C$6:$C$1997,B10) -> 2 | U10: =SUM(M10:R10) -> 0 | V10: =IF(B10="","",J10) -> 0
A11: 4 | B11: A.01.0782.001.2G | C11: =IF(B11="","",IFERROR(IF(TRIM(MID(SUBSTITUTE(B11,".",REPT(" ",50)),51,50))="01","Masculino",IF(TRIM(MID(SUBSTITUTE(B11,".",REPT(" ",50)),51,50))="02","Feminino",IF(TRIM(MID(SUBSTITUTE(B11,".",REPT(" ",50)),51,50))="03","Outros","—"))),"—")) -> Masculino | D11: =IFERROR(INDEX(SKUs!$E$6:$E$1997,MATCH(B11,SKUs!$C$6:$C$1997,0)),"") -> POLO | E11: =IFERROR(VLOOKUP(D11,Configurações!$N$5:$O$46,2,FALSE()),"OUTROS") -> VESTUÁRIO | F11: =IFERROR(INDEX(SKUs!$F$6:$F$1997,MATCH(B11,SKUs!$C$6:$C$1997,0)),"") -> POLO COPA MASC. | G11: =IFERROR(INDEX(SKUs!$G$6:$G$1997,MATCH(B11,SKUs!$C$6:$C$1997,0)),"") -> AZUL | H11: =IFERROR(INDEX(SKUs!$H$6:$H$1997,MATCH(B11,SKUs!$C$6:$C$1997,0)),"") -> P | I11: =IFERROR(INDEX(SKUs!#REF!,MATCH(B11,SKUs!$C$6:$C$1997,0)),"") | J11: =SUMIFS(SKUs!$I$6:$I$1997,SKUs!$C$6:$C$1997,B11) -> 0 | K11: =IFERROR(I11*J11,0) -> 0 | L11: =COUNTIF(SKUs!$C$6:$C$1997,B11) -> 2 | U11: =SUM(M11:R11) -> 0 | V11: =IF(B11="","",J11) -> 0
A12: 5 | B12: A.01.0782.001.3G | C12: =IF(B12="","",IFERROR(IF(TRIM(MID(SUBSTITUTE(B12,".",REPT(" ",50)),51,50))="01","Masculino",IF(TRIM(MID(SUBSTITUTE(B12,".",REPT(" ",50)),51,50))="02","Feminino",IF(TRIM(MID(SUBSTITUTE(B12,".",REPT(" ",50)),51,50))="03","Outros","—"))),"—")) -> Masculino | D12: =IFERROR(INDEX(SKUs!$E$6:$E$1997,MATCH(B12,SKUs!$C$6:$C$1997,0)),"") -> POLO | E12: =IFERROR(VLOOKUP(D12,Configurações!$N$5:$O$46,2,FALSE()),"OUTROS") -> VESTUÁRIO | F12: =IFERROR(INDEX(SKUs!$F$6:$F$1997,MATCH(B12,SKUs!$C$6:$C$1997,0)),"") -> POLO COPA MASC. | G12: =IFERROR(INDEX(SKUs!$G$6:$G$1997,MATCH(B12,SKUs!$C$6:$C$1997,0)),"") -> AZUL | H12: =IFERROR(INDEX(SKUs!$H$6:$H$1997,MATCH(B12,SKUs!$C$6:$C$1997,0)),"") -> GG | I12: =IFERROR(INDEX(SKUs!#REF!,MATCH(B12,SKUs!$C$6:$C$1997,0)),"") | J12: =SUMIFS(SKUs!$I$6:$I$1997,SKUs!$C$6:$C$1997,B12) -> 0 | K12: =IFERROR(I12*J12,0) -> 0 | L12: =COUNTIF(SKUs!$C$6:$C$1997,B12) -> 1 | U12: =SUM(M12:R12) -> 0 | V12: =IF(B12="","",J12) -> 0
A13: 6 | B13: A.01.0782.001.4G | C13: =IF(B13="","",IFERROR(IF(TRIM(MID(SUBSTITUTE(B13,".",REPT(" ",50)),51,50))="01","Masculino",IF(TRIM(MID(SUBSTITUTE(B13,".",REPT(" ",50)),51,50))="02","Feminino",IF(TRIM(MID(SUBSTITUTE(B13,".",REPT(" ",50)),51,50))="03","Outros","—"))),"—")) -> Masculino | D13: =IFERROR(INDEX(SKUs!$E$6:$E$1997,MATCH(B13,SKUs!$C$6:$C$1997,0)),"") -> CAMISETA | E13: =IFERROR(VLOOKUP(D13,Configurações!$N$5:$O$46,2,FALSE()),"OUTROS") -> VESTUÁRIO | F13: =IFERROR(INDEX(SKUs!$F$6:$F$1997,MATCH(B13,SKUs!$C$6:$C$1997,0)),"") -> CAMISETA COPA MASC. | G13: =IFERROR(INDEX(SKUs!$G$6:$G$1997,MATCH(B13,SKUs!$C$6:$C$1997,0)),"") -> AZUL | H13: =IFERROR(INDEX(SKUs!$H$6:$H$1997,MATCH(B13,SKUs!$C$6:$C$1997,0)),"") -> P | I13: =IFERROR(INDEX(SKUs!#REF!,MATCH(B13,SKUs!$C$6:$C$1997,0)),"") | J13: =SUMIFS(SKUs!$I$6:$I$1997,SKUs!$C$6:$C$1997,B13) -> 0 | K13: =IFERROR(I13*J13,0) -> 0 | L13: =COUNTIF(SKUs!$C$6:$C$1997,B13) -> 1 | U13: =SUM(M13:R13) -> 0 | V13: =IF(B13="","",J13) -> 0
A14: 7 | B14: A.01.0776.001.M | C14: =IF(B14="","",IFERROR(IF(TRIM(MID(SUBSTITUTE(B14,".",REPT(" ",50)),51,50))="01","Masculino",IF(TRIM(MID(SUBSTITUTE(B14,".",REPT(" ",50)),51,50))="02","Feminino",IF(TRIM(MID(SUBSTITUTE(B14,".",REPT(" ",50)),51,50))="03","Outros","—"))),"—")) -> Masculino | D14: =IFERROR(INDEX(SKUs!$E$6:$E$1997,MATCH(B14,SKUs!$C$6:$C$1997,0)),"") -> CAMISETA | E14: =IFERROR(VLOOKUP(D14,Configurações!$N$5:$O$46,2,FALSE()),"OUTROS") -> VESTUÁRIO | F14: =IFERROR(INDEX(SKUs!$F$6:$F$1997,MATCH(B14,SKUs!$C$6:$C$1997,0)),"") -> CAMISETA COPA MASC. | G14: =IFERROR(INDEX(SKUs!$G$6:$G$1997,MATCH(B14,SKUs!$C$6:$C$1997,0)),"") -> AZUL | H14: =IFERROR(INDEX(SKUs!$H$6:$H$1997,MATCH(B14,SKUs!$C$6:$C$1997,0)),"") -> M | I14: =IFERROR(INDEX(SKUs!#REF!,MATCH(B14,SKUs!$C$6:$C$1997,0)),"") | J14: =SUMIFS(SKUs!$I$6:$I$1997,SKUs!$C$6:$C$1997,B14) -> 0 | K14: =IFERROR(I14*J14,0) -> 0 | L14: =COUNTIF(SKUs!$C$6:$C$1997,B14) -> 1 | U14: =SUM(M14:R14) -> 0 | V14: =IF(B14="","",J14) -> 0
A15: 8 | B15: A.01.0776.001.G | C15: =IF(B15="","",IFERROR(IF(TRIM(MID(SUBSTITUTE(B15,".",REPT(" ",50)),51,50))="01","Masculino",IF(TRIM(MID(SUBSTITUTE(B15,".",REPT(" ",50)),51,50))="02","Feminino",IF(TRIM(MID(SUBSTITUTE(B15,".",REPT(" ",50)),51,50))="03","Outros","—"))),"—")) -> Masculino | D15: =IFERROR(INDEX(SKUs!$E$6:$E$1997,MATCH(B15,SKUs!$C$6:$C$1997,0)),"") -> CAMISETA | E15: =IFERROR(VLOOKUP(D15,Configurações!$N$5:$O$46,2,FALSE()),"OUTROS") -> VESTUÁRIO | F15: =IFERROR(INDEX(SKUs!$F$6:$F$1997,MATCH(B15,SKUs!$C$6:$C$1997,0)),"") -> CAMISETA COPA MASC. | G15: =IFERROR(INDEX(SKUs!$G$6:$G$1997,MATCH(B15,SKUs!$C$6:$C$1997,0)),"") -> AZUL | H15: =IFERROR(INDEX(SKUs!$H$6:$H$1997,MATCH(B15,SKUs!$C$6:$C$1997,0)),"") -> GG | I15: =IFERROR(INDEX(SKUs!#REF!,MATCH(B15,SKUs!$C$6:$C$1997,0)),"") | J15: =SUMIFS(SKUs!$I$6:$I$1997,SKUs!$C$6:$C$1997,B15) -> 0 | K15: =IFERROR(I15*J15,0) -> 0 | L15: =COUNTIF(SKUs!$C$6:$C$1997,B15) -> 1 | U15: =SUM(M15:R15) -> 0 | V15: =IF(B15="","",J15) -> 0
A16: 9 | B16: A.01.0776.001.2G | C16: =IF(B16="","",IFERROR(IF(TRIM(MID(SUBSTITUTE(B16,".",REPT(" ",50)),51,50))="01","Masculino",IF(TRIM(MID(SUBSTITUTE(B16,".",REPT(" ",50)),51,50))="02","Feminino",IF(TRIM(MID(SUBSTITUTE(B16,".",REPT(" ",50)),51,50))="03","Outros","—"))),"—")) -> Masculino | D16: =IFERROR(INDEX(SKUs!$E$6:$E$1997,MATCH(B16,SKUs!$C$6:$C$1997,0)),"") -> CAMISETA | E16: =IFERROR(VLOOKUP(D16,Configurações!$N$5:$O$46,2,FALSE()),"OUTROS") -> VESTUÁRIO | F16: =IFERROR(INDEX(SKUs!$F$6:$F$1997,MATCH(B16,SKUs!$C$6:$C$1997,0)),"") -> CAMISETA COPA MASC. | G16: =IFERROR(INDEX(SKUs!$G$6:$G$1997,MATCH(B16,SKUs!$C$6:$C$1997,0)),"") -> AZUL | H16: =IFERROR(INDEX(SKUs!$H$6:$H$1997,MATCH(B16,SKUs!$C$6:$C$1997,0)),"") -> G | I16: =IFERROR(INDEX(SKUs!#REF!,MATCH(B16,SKUs!$C$6:$C$1997,0)),"") | J16: =SUMIFS(SKUs!$I$6:$I$1997,SKUs!$C$6:$C$1997,B16) -> 0 | K16: =IFERROR(I16*J16,0) -> 0 | L16: =COUNTIF(SKUs!$C$6:$C$1997,B16) -> 1 | U16: =SUM(M16:R16) -> 0 | V16: =IF(B16="","",J16) -> 0
A17: 10 | B17: A.01.0776.001.3G | C17: =IF(B17="","",IFERROR(IF(TRIM(MID(SUBSTITUTE(B17,".",REPT(" ",50)),51,50))="01","Masculino",IF(TRIM(MID(SUBSTITUTE(B17,".",REPT(" ",50)),51,50))="02","Feminino",IF(TRIM(MID(SUBSTITUTE(B17,".",REPT(" ",50)),51,50))="03","Outros","—"))),"—")) -> Masculino | D17: =IFERROR(INDEX(SKUs!$E$6:$E$1997,MATCH(B17,SKUs!$C$6:$C$1997,0)),"") -> CAMISETA | E17: =IFERROR(VLOOKUP(D17,Configurações!$N$5:$O$46,2,FALSE()),"OUTROS") -> VESTUÁRIO | F17: =IFERROR(INDEX(SKUs!$F$6:$F$1997,MATCH(B17,SKUs!$C$6:$C$1997,0)),"") -> CAMISETA COPA MASC. | G17: =IFERROR(INDEX(SKUs!$G$6:$G$1997,MATCH(B17,SKUs!$C$6:$C$1997,0)),"") -> AZUL | H17: =IFERROR(INDEX(SKUs!$H$6:$H$1997,MATCH(B17,SKUs!$C$6:$C$1997,0)),"") -> XG | I17: =IFERROR(INDEX(SKUs!#REF!,MATCH(B17,SKUs!$C$6:$C$1997,0)),"") | J17: =SUMIFS(SKUs!$I$6:$I$1997,SKUs!$C$6:$C$1997,B17) -> 0 | K17: =IFERROR(I17*J17,0) -> 0 | L17: =COUNTIF(SKUs!$C$6:$C$1997,B17) -> 1 | U17: =SUM(M17:R17) -> 0 | V17: =IF(B17="","",J17) -> 0
A18: 11 | B18: A.01.0776.001.4G | C18: =IF(B18="","",IFERROR(IF(TRIM(MID(SUBSTITUTE(B18,".",REPT(" ",50)),51,50))="01","Masculino",IF(TRIM(MID(SUBSTITUTE(B18,".",REPT(" ",50)),51,50))="02","Feminino",IF(TRIM(MID(SUBSTITUTE(B18,".",REPT(" ",50)),51,50))="03","Outros","—"))),"—")) -> Masculino | D18: =IFERROR(INDEX(SKUs!$E$6:$E$1997,MATCH(B18,SKUs!$C$6:$C$1997,0)),"") -> CAMISETA | E18: =IFERROR(VLOOKUP(D18,Configurações!$N$5:$O$46,2,FALSE()),"OUTROS") -> VESTUÁRIO | F18: =IFERROR(INDEX(SKUs!$F$6:$F$1997,MATCH(B18,SKUs!$C$6:$C$1997,0)),"") -> CAMISETA COPA MASC. | G18: =IFERROR(INDEX(SKUs!$G$6:$G$1997,MATCH(B18,SKUs!$C$6:$C$1997,0)),"") -> AZUL | H18: =IFERROR(INDEX(SKUs!$H$6:$H$1997,MATCH(B18,SKUs!$C$6:$C$1997,0)),"") -> 4G | I18: =IFERROR(INDEX(SKUs!#REF!,MATCH(B18,SKUs!$C$6:$C$1997,0)),"") | J18: =SUMIFS(SKUs!$I$6:$I$1997,SKUs!$C$6:$C$1997,B18) -> 0 | K18: =IFERROR(I18*J18,0) -> 0 | L18: =COUNTIF(SKUs!$C$6:$C$1997,B18) -> 1 | U18: =SUM(M18:R18) -> 0 | V18: =IF(B18="","",J18) -> 0
A19: 12 | B19: A.01.0778.009.P | C19: =IF(B19="","",IFERROR(IF(TRIM(MID(SUBSTITUTE(B19,".",REPT(" ",50)),51,50))="01","Masculino",IF(TRIM(MID(SUBSTITUTE(B19,".",REPT(" ",50)),51,50))="02","Feminino",IF(TRIM(MID(SUBSTITUTE(B19,".",REPT(" ",50)),51,50))="03","Outros","—"))),"—")) -> Masculino | D19: =IFERROR(INDEX(SKUs!$E$6:$E$1997,MATCH(B19,SKUs!$C$6:$C$1997,0)),"") -> CAMISETA | E19: =IFERROR(VLOOKUP(D19,Configurações!$N$5:$O$46,2,FALSE()),"OUTROS") -> VESTUÁRIO | F19: =IFERROR(INDEX(SKUs!$F$6:$F$1997,MATCH(B19,SKUs!$C$6:$C$1997,0)),"") -> CAMISETA COPA MASC. | G19: =IFERROR(INDEX(SKUs!$G$6:$G$1997,MATCH(B19,SKUs!$C$6:$C$1997,0)),"") -> AMARELA | H19: =IFERROR(INDEX(SKUs!$H$6:$H$1997,MATCH(B19,SKUs!$C$6:$C$1997,0)),"") -> P | I19: =IFERROR(INDEX(SKUs!#REF!,MATCH(B19,SKUs!$C$6:$C$1997,0)),"") | J19: =SUMIFS(SKUs!$I$6:$I$1997,SKUs!$C$6:$C$1997,B19) -> 0 | K19: =IFERROR(I19*J19,0) -> 0 | L19: =COUNTIF(SKUs!$C$6:$C$1997,B19) -> 1 | U19: =SUM(M19:R19) -> 0 | V19: =IF(B19="","",J19) -> 0
... A37: 30 | B37: A.01.0768.011.G | C37: =IF(B37="","",IFERROR(IF(TRIM(MID(SUBSTITUTE(B37,".",REPT(" ",50)),51,50))="01","Masculino",IF(TRIM(MID(SUBSTITUTE(B37,".",REPT(" ",50)),51,50))="02","Feminino",IF(TRIM(MID(SUBSTITUTE(B37,".",REPT(" ",50)),51,50))="03","Outros","—"))),"—")) -> Masculino | D37: =IFERROR(INDEX(SKUs!$E$6:$E$1997,MATCH(B37,SKUs!$C$6:$C$1997,0)),"") -> JAQUETA | E37: =IFERROR(VLOOKUP(D37,Configurações!$N$5:$O$46,2,FALSE()),"OUTROS") -> VESTUÁRIO | F37: =IFERROR(INDEX(SKUs!$F$6:$F$1997,MATCH(B37,SKUs!$C$6:$C$1997,0)),"") -> JAQUETA COPA MASC. | G37: =IFERROR(INDEX(SKUs!$G$6:$G$1997,MATCH(B37,SKUs!$C$6:$C$1997,0)),"") -> VERDE | H37: =IFERROR(INDEX(SKUs!$H$6:$H$1997,MATCH(B37,SKUs!$C$6:$C$1997,0)),"") -> G | I37: =IFERROR(INDEX(SKUs!#REF!,MATCH(B37,SKUs!$C$6:$C$1997,0)),"") | J37: =SUMIFS(SKUs!$I$6:$I$1997,SKUs!$C$6:$C$1997,B37) -> 10 | K37: =IFERROR(I37*J37,0) -> 0 | L37: =COUNTIF(SKUs!$C$6:$C$1997,B37) -> 1 | U37: =SUM(M37:R37) -> 0 | V37: =IF(B37="","",J37) -> 10
A38: 31 | B38: A.01.0768.011.GG | C38: =IF(B38="","",IFERROR(IF(TRIM(MID(SUBSTITUTE(B38,".",REPT(" ",50)),51,50))="01","Masculino",IF(TRIM(MID(SUBSTITUTE(B38,".",REPT(" ",50)),51,50))="02","Feminino",IF(TRIM(MID(SUBSTITUTE(B38,".",REPT(" ",50)),51,50))="03","Outros","—"))),"—")) -> Masculino | D38: =IFERROR(INDEX(SKUs!$E$6:$E$1997,MATCH(B38,SKUs!$C$6:$C$1997,0)),"") -> JAQUETA | E38: =IFERROR(VLOOKUP(D38,Configurações!$N$5:$O$46,2,FALSE()),"OUTROS") -> VESTUÁRIO | F38: =IFERROR(INDEX(SKUs!$F$6:$F$1997,MATCH(B38,SKUs!$C$6:$C$1997,0)),"") -> JAQUETA COPA MASC. | G38: =IFERROR(INDEX(SKUs!$G$6:$G$1997,MATCH(B38,SKUs!$C$6:$C$1997,0)),"") -> VERDE | H38: =IFERROR(INDEX(SKUs!$H$6:$H$1997,MATCH(B38,SKUs!$C$6:$C$1997,0)),"") -> GG | I38: =IFERROR(INDEX(SKUs!#REF!,MATCH(B38,SKUs!$C$6:$C$1997,0)),"") | J38: =SUMIFS(SKUs!$I$6:$I$1997,SKUs!$C$6:$C$1997,B38) -> 0 | K38: =IFERROR(I38*J38,0) -> 0 | L38: =COUNTIF(SKUs!$C$6:$C$1997,B38) -> 2 | M38: 10 | U38: =SUM(M38:R38) -> 10 | V38: =IF(B38="","",J38) -> 0
A39: 32 | B39: A.01.0768.011.XG | C39: =IF(B39="","",IFERROR(IF(TRIM(MID(SUBSTITUTE(B39,".",REPT(" ",50)),51,50))="01","Masculino",IF(TRIM(MID(SUBSTITUTE(B39,".",REPT(" ",50)),51,50))="02","Feminino",IF(TRIM(MID(SUBSTITUTE(B39,".",REPT(" ",50)),51,50))="03","Outros","—"))),"—")) -> Masculino | D39: =IFERROR(INDEX(SKUs!$E$6:$E$1997,MATCH(B39,SKUs!$C$6:$C$1997,0)),"") -> JAQUETA | E39: =IFERROR(VLOOKUP(D39,Configurações!$N$5:$O$46,2,FALSE()),"OUTROS") -> VESTUÁRIO | F39: =IFERROR(INDEX(SKUs!$F$6:$F$1997,MATCH(B39,SKUs!$C$6:$C$1997,0)),"") -> JAQUETA COPA MASC. | G39: =IFERROR(INDEX(SKUs!$G$6:$G$1997,MATCH(B39,SKUs!$C$6:$C$1997,0)),"") -> VERDE | H39: =IFERROR(INDEX(SKUs!$H$6:$H$1997,MATCH(B39,SKUs!$C$6:$C$1997,0)),"") -> XG | I39: =IFERROR(INDEX(SKUs!#REF!,MATCH(B39,SKUs!$C$6:$C$1997,0)),"") | J39: =SUMIFS(SKUs!$I$6:$I$1997,SKUs!$C$6:$C$1997,B39) -> 0 | K39: =IFERROR(I39*J39,0) -> 0 | L39: =COUNTIF(SKUs!$C$6:$C$1997,B39) -> 1 | M39: 10 | U39: =SUM(M39:R39) -> 10 | V39: =IF(B39="","",J39) -> 0
A40: 33 | B40: A.01.0772.001.P | C40: =IF(B40="","",IFERROR(IF(TRIM(MID(SUBSTITUTE(B40,".",REPT(" ",50)),51,50))="01","Masculino",IF(TRIM(MID(SUBSTITUTE(B40,".",REPT(" ",50)),51,50))="02","Feminino",IF(TRIM(MID(SUBSTITUTE(B40,".",REPT(" ",50)),51,50))="03","Outros","—"))),"—")) -> Masculino | D40: =IFERROR(INDEX(SKUs!$E$6:$E$1997,MATCH(B40,SKUs!$C$6:$C$1997,0)),"") -> JAQUETA | E40: =IFERROR(VLOOKUP(D40,Configurações!$N$5:$O$46,2,FALSE()),"OUTROS") -> VESTUÁRIO | F40: =IFERROR(INDEX(SKUs!$F$6:$F$1997,MATCH(B40,SKUs!$C$6:$C$1997,0)),"") -> JAQUETA COPA MASC. | G40: =IFERROR(INDEX(SKUs!$G$6:$G$1997,MATCH(B40,SKUs!$C$6:$C$1997,0)),"") -> AZUL | H40: =IFERROR(INDEX(SKUs!$H$6:$H$1997,MATCH(B40,SKUs!$C$6:$C$1997,0)),"") -> P | I40: =IFERROR(INDEX(SKUs!#REF!,MATCH(B40,SKUs!$C$6:$C$1997,0)),"") | J40: =SUMIFS(SKUs!$I$6:$I$1997,SKUs!$C$6:$C$1997,B40) -> 10 | K40: =IFERROR(I40*J40,0) -> 0 | L40: =COUNTIF(SKUs!$C$6:$C$1997,B40) -> 1 | U40: =SUM(M40:R40) -> 0 | V40: =IF(B40="","",J40) -> 10
A41: 34 | B41: A.01.0772.001.M | C41: =IF(B41="","",IFERROR(IF(TRIM(MID(SUBSTITUTE(B41,".",REPT(" ",50)),51,50))="01","Masculino",IF(TRIM(MID(SUBSTITUTE(B41,".",REPT(" ",50)),51,50))="02","Feminino",IF(TRIM(MID(SUBSTITUTE(B41,".",REPT(" ",50)),51,50))="03","Outros","—"))),"—")) -> Masculino | D41: =IFERROR(INDEX(SKUs!$E$6:$E$1997,MATCH(B41,SKUs!$C$6:$C$1997,0)),"") -> JAQUETA | E41: =IFERROR(VLOOKUP(D41,Configurações!$N$5:$O$46,2,FALSE()),"OUTROS") -> VESTUÁRIO | F41: =IFERROR(INDEX(SKUs!$F$6:$F$1997,MATCH(B41,SKUs!$C$6:$C$1997,0)),"") -> JAQUETA COPA MASC. | G41: =IFERROR(INDEX(SKUs!$G$6:$G$1997,MATCH(B41,SKUs!$C$6:$C$1997,0)),"") -> AZUL | H41: =IFERROR(INDEX(SKUs!$H$6:$H$1997,MATCH(B41,SKUs!$C$6:$C$1997,0)),"") -> M | I41: =IFERROR(INDEX(SKUs!#REF!,MATCH(B41,SKUs!$C$6:$C$1997,0)),"") | J41: =SUMIFS(SKUs!$I$6:$I$1997,SKUs!$C$6:$C$1997,B41) -> 10 | K41: =IFERROR(I41*J41,0) -> 0 | L41: =COUNTIF(SKUs!$C$6:$C$1997,B41) -> 1 | U41: =SUM(M41:R41) -> 0 | V41: =IF(B41="","",J41) -> 10
A42: 35 | B42: A.01.0772.001.G | C42: =IF(B42="","",IFERROR(IF(TRIM(MID(SUBSTITUTE(B42,".",REPT(" ",50)),51,50))="01","Masculino",IF(TRIM(MID(SUBSTITUTE(B42,".",REPT(" ",50)),51,50))="02","Feminino",IF(TRIM(MID(SUBSTITUTE(B42,".",REPT(" ",50)),51,50))="03","Outros","—"))),"—")) -> Masculino | D42: =IFERROR(INDEX(SKUs!$E$6:$E$1997,MATCH(B42,SKUs!$C$6:$C$1997,0)),"") -> JAQUETA | E42: =IFERROR(VLOOKUP(D42,Configurações!$N$5:$O$46,2,FALSE()),"OUTROS") -> VESTUÁRIO | F42: =IFERROR(INDEX(SKUs!$F$6:$F$1997,MATCH(B42,SKUs!$C$6:$C$1997,0)),"") -> JAQUETA COPA MASC. | G42: =IFERROR(INDEX(SKUs!$G$6:$G$1997,MATCH(B42,SKUs!$C$6:$C$1997,0)),"") -> AZUL | H42: =IFERROR(INDEX(SKUs!$H$6:$H$1997,MATCH(B42,SKUs!$C$6:$C$1997,0)),"") -> G | I42: =IFERROR(INDEX(SKUs!#REF!,MATCH(B42,SKUs!$C$6:$C$1997,0)),"") | J42: =SUMIFS(SKUs!$I$6:$I$1997,SKUs!$C$6:$C$1997,B42) -> 9 | K42: =IFERROR(I42*J42,0) -> 0 | L42: =COUNTIF(SKUs!$C$6:$C$1997,B42) -> 2 | U42: =SUM(M42:R42) -> 0 | V42: =IF(B42="","",J42) -> 9
A43: 36 | B43: A.01.0772.001.GG | C43: =IF(B43="","",IFERROR(IF(TRIM(MID(SUBSTITUTE(B43,".",REPT(" ",50)),51,50))="01","Masculino",IF(TRIM(MID(SUBSTITUTE(B43,".",REPT(" ",50)),51,50))="02","Feminino",IF(TRIM(MID(SUBSTITUTE(B43,".",REPT(" ",50)),51,50))="03","Outros","—"))),"—")) -> Masculino | D43: =IFERROR(INDEX(SKUs!$E$6:$E$1997,MATCH(B43,SKUs!$C$6:$C$1997,0)),"") -> JAQUETA | E43: =IFERROR(VLOOKUP(D43,Configurações!$N$5:$O$46,2,FALSE()),"OUTROS") -> VESTUÁRIO | F43: =IFERROR(INDEX(SKUs!$F$6:$F$1997,MATCH(B43,SKUs!$C$6:$C$1997,0)),"") -> JAQUETA COPA MASC. | G43: =IFERROR(INDEX(SKUs!$G$6:$G$1997,MATCH(B43,SKUs!$C$6:$C$1997,0)),"") -> AZUL | H43: =IFERROR(INDEX(SKUs!$H$6:$H$1997,MATCH(B43,SKUs!$C$6:$C$1997,0)),"") -> GG | I43: =IFERROR(INDEX(SKUs!#REF!,MATCH(B43,SKUs!$C$6:$C$1997,0)),"") | J43: =SUMIFS(SKUs!$I$6:$I$1997,SKUs!$C$6:$C$1997,B43) -> 9 | K43: =IFERROR(I43*J43,0) -> 0 | L43: =COUNTIF(SKUs!$C$6:$C$1997,B43) -> 1 | U43: =SUM(M43:R43) -> 0 | V43: =IF(B43="","",J43) -> 9
A44: 37 | B44: A.01.0772.001.XG | C44: =IF(B44="","",IFERROR(IF(TRIM(MID(SUBSTITUTE(B44,".",REPT(" ",50)),51,50))="01","Masculino",IF(TRIM(MID(SUBSTITUTE(B44,".",REPT(" ",50)),51,50))="02","Feminino",IF(TRIM(MID(SUBSTITUTE(B44,".",REPT(" ",50)),51,50))="03","Outros","—"))),"—")) -> Masculino | D44: =IFERROR(INDEX(SKUs!$E$6:$E$1997,MATCH(B44,SKUs!$C$6:$C$1997,0)),"") -> JAQUETA | E44: =IFERROR(VLOOKUP(D44,Configurações!$N$5:$O$46,2,FALSE()),"OUTROS") -> VESTUÁRIO | F44: =IFERROR(INDEX(SKUs!$F$6:$F$1997,MATCH(B44,SKUs!$C$6:$C$1997,0)),"") -> JAQUETA COPA MASC. | G44: =IFERROR(INDEX(SKUs!$G$6:$G$1997,MATCH(B44,SKUs!$C$6:$C$1997,0)),"") -> AZUL | H44: =IFERROR(INDEX(SKUs!$H$6:$H$1997,MATCH(B44,SKUs!$C$6:$C$1997,0)),"") -> XG | I44: =IFERROR(INDEX(SKUs!#REF!,MATCH(B44,SKUs!$C$6:$C$1997,0)),"") | J44: =SUMIFS(SKUs!$I$6:$I$1997,SKUs!$C$6:$C$1997,B44) -> 11 | K44: =IFERROR(I44*J44,0) -> 0 | L44: =COUNTIF(SKUs!$C$6:$C$1997,B44) -> 1 | U44: =SUM(M44:R44) -> 0 | V44: =IF(B44="","",J44) -> 11
A45: 38 | B45: A.01.0766.003.P | C45: =IF(B45="","",IFERROR(IF(TRIM(MID(SUBSTITUTE(B45,".",REPT(" ",50)),51,50))="01","Masculino",IF(TRIM(MID(SUBSTITUTE(B45,".",REPT(" ",50)),51,50))="02","Feminino",IF(TRIM(MID(SUBSTITUTE(B45,".",REPT(" ",50)),51,50))="03","Outros","—"))),"—")) -> Masculino | D45: =IFERROR(INDEX(SKUs!$E$6:$E$1997,MATCH(B45,SKUs!$C$6:$C$1997,0)),"") -> JAQUETA | E45: =IFERROR(VLOOKUP(D45,Configurações!$N$5:$O$46,2,FALSE()),"OUTROS") -> VESTUÁRIO | F45: =IFERROR(INDEX(SKUs!$F$6:$F$1997,MATCH(B45,SKUs!$C$6:$C$1997,0)),"") -> JAQUETA COPA MASC. | G45: =IFERROR(INDEX(SKUs!$G$6:$G$1997,MATCH(B45,SKUs!$C$6:$C$1997,0)),"") -> BRANCA | H45: =IFERROR(INDEX(SKUs!$H$6:$H$1997,MATCH(B45,SKUs!$C$6:$C$1997,0)),"") -> P | I45: =IFERROR(INDEX(SKUs!#REF!,MATCH(B45,SKUs!$C$6:$C$1997,0)),"") | J45: =SUMIFS(SKUs!$I$6:$I$1997,SKUs!$C$6:$C$1997,B45) -> 10 | K45: =IFERROR(I45*J45,0) -> 0 | L45: =COUNTIF(SKUs!$C$6:$C$1997,B45) -> 2 | U45: =SUM(M45:R45) -> 0 | V45: =IF(B45="","",J45) -> 10
A46: 39 | B46: A.01.0766.003.M | C46: =IF(B46="","",IFERROR(IF(TRIM(MID(SUBSTITUTE(B46,".",REPT(" ",50)),51,50))="01","Masculino",IF(TRIM(MID(SUBSTITUTE(B46,".",REPT(" ",50)),51,50))="02","Feminino",IF(TRIM(MID(SUBSTITUTE(B46,".",REPT(" ",50)),51,50))="03","Outros","—"))),"—")) -> Masculino | D46: =IFERROR(INDEX(SKUs!$E$6:$E$1997,MATCH(B46,SKUs!$C$6:$C$1997,0)),"") -> JAQUETA | E46: =IFERROR(VLOOKUP(D46,Configurações!$N$5:$O$46,2,FALSE()),"OUTROS") -> VESTUÁRIO | F46: =IFERROR(INDEX(SKUs!$F$6:$F$1997,MATCH(B46,SKUs!$C$6:$C$1997,0)),"") -> JAQUETA COPA MASC. | G46: =IFERROR(INDEX(SKUs!$G$6:$G$1997,MATCH(B46,SKUs!$C$6:$C$1997,0)),"") -> BRANCA | H46: =IFERROR(INDEX(SKUs!$H$6:$H$1997,MATCH(B46,SKUs!$C$6:$C$1997,0)),"") -> M | I46: =IFERROR(INDEX(SKUs!#REF!,MATCH(B46,SKUs!$C$6:$C$1997,0)),"") | J46: =SUMIFS(SKUs!$I$6:$I$1997,SKUs!$C$6:$C$1997,B46) -> 8 | K46: =IFERROR(I46*J46,0) -> 0 | L46: =COUNTIF(SKUs!$C$6:$C$1997,B46) -> 1 | U46: =SUM(M46:R46) -> 0 | V46: =IF(B46="","",J46) -> 8
A47: 40 | B47: A.01.0766.003.G | C47: =IF(B47="","",IFERROR(IF(TRIM(MID(SUBSTITUTE(B47,".",REPT(" ",50)),51,50))="01","Masculino",IF(TRIM(MID(SUBSTITUTE(B47,".",REPT(" ",50)),51,50))="02","Feminino",IF(TRIM(MID(SUBSTITUTE(B47,".",REPT(" ",50)),51,50))="03","Outros","—"))),"—")) -> Masculino | D47: =IFERROR(INDEX(SKUs!$E$6:$E$1997,MATCH(B47,SKUs!$C$6:$C$1997,0)),"") -> JAQUETA | E47: =IFERROR(VLOOKUP(D47,Configurações!$N$5:$O$46,2,FALSE()),"OUTROS") -> VESTUÁRIO | F47: =IFERROR(INDEX(SKUs!$F$6:$F$1997,MATCH(B47,SKUs!$C$6:$C$1997,0)),"") -> JAQUETA COPA MASC. | G47: =IFERROR(INDEX(SKUs!$G$6:$G$1997,MATCH(B47,SKUs!$C$6:$C$1997,0)),"") -> BRANCA | H47: =IFERROR(INDEX(SKUs!$H$6:$H$1997,MATCH(B47,SKUs!$C$6:$C$1997,0)),"") -> G | I47: =IFERROR(INDEX(SKUs!#REF!,MATCH(B47,SKUs!$C$6:$C$1997,0)),"") | J47: =SUMIFS(SKUs!$I$6:$I$1997,SKUs!$C$6:$C$1997,B47) -> 11 | K47: =IFERROR(I47*J47,0) -> 0 | L47: =COUNTIF(SKUs!$C$6:$C$1997,B47) -> 1 | U47: =SUM(M47:R47) -> 0 | V47: =IF(B47="","",J47) -> 11
A48: 41 | B48: A.01.0766.003.GG | C48: =IF(B48="","",IFERROR(IF(TRIM(MID(SUBSTITUTE(B48,".",REPT(" ",50)),51,50))="01","Masculino",IF(TRIM(MID(SUBSTITUTE(B48,".",REPT(" ",50)),51,50))="02","Feminino",IF(TRIM(MID(SUBSTITUTE(B48,".",REPT(" ",50)),51,50))="03","Outros","—"))),"—")) -> Masculino | D48: =IFERROR(INDEX(SKUs!$E$6:$E$1997,MATCH(B48,SKUs!$C$6:$C$1997,0)),"") -> JAQUETA | E48: =IFERROR(VLOOKUP(D48,Configurações!$N$5:$O$46,2,FALSE()),"OUTROS") -> VESTUÁRIO | F48: =IFERROR(INDEX(SKUs!$F$6:$F$1997,MATCH(B48,SKUs!$C$6:$C$1997,0)),"") -> JAQUETA COPA MASC. | G48: =IFERROR(INDEX(SKUs!$G$6:$G$1997,MATCH(B48,SKUs!$C$6:$C$1997,0)),"") -> BRANCA | H48: =IFERROR(INDEX(SKUs!$H$6:$H$1997,MATCH(B48,SKUs!$C$6:$C$1997,0)),"") -> GG | I48: =IFERROR(INDEX(SKUs!#REF!,MATCH(B48,SKUs!$C$6:$C$1997,0)),"") | J48: =SUMIFS(SKUs!$I$6:$I$1997,SKUs!$C$6:$C$1997,B48) -> 9 | K48: =IFERROR(I48*J48,0) -> 0 | L48: =COUNTIF(SKUs!$C$6:$C$1997,B48) -> 1 | U48: =SUM(M48:R48) -> 0 | V48: =IF(B48="","",J48) -> 9
A49: 42 | B49: A.01.0766.003.XG | C49: =IF(B49="","",IFERROR(IF(TRIM(MID(SUBSTITUTE(B49,".",REPT(" ",50)),51,50))="01","Masculino",IF(TRIM(MID(SUBSTITUTE(B49,".",REPT(" ",50)),51,50))="02","Feminino",IF(TRIM(MID(SUBSTITUTE(B49,".",REPT(" ",50)),51,50))="03","Outros","—"))),"—")) -> Masculino | D49: =IFERROR(INDEX(SKUs!$E$6:$E$1997,MATCH(B49,SKUs!$C$6:$C$1997,0)),"") -> JAQUETA | E49: =IFERROR(VLOOKUP(D49,Configurações!$N$5:$O$46,2,FALSE()),"OUTROS") -> VESTUÁRIO | F49: =IFERROR(INDEX(SKUs!$F$6:$F$1997,MATCH(B49,SKUs!$C$6:$C$1997,0)),"") -> JAQUETA COPA MASC. | G49: =IFERROR(INDEX(SKUs!$G$6:$G$1997,MATCH(B49,SKUs!$C$6:$C$1997,0)),"") -> BRANCA | H49: =IFERROR(INDEX(SKUs!$H$6:$H$1997,MATCH(B49,SKUs!$C$6:$C$1997,0)),"") -> XG | I49: =IFERROR(INDEX(SKUs!#REF!,MATCH(B49,SKUs!$C$6:$C$1997,0)),"") | J49: =SUMIFS(SKUs!$I$6:$I$1997,SKUs!$C$6:$C$1997,B49) -> 8 | K49: =IFERROR(I49*J49,0) -> 0 | L49: =COUNTIF(SKUs!$C$6:$C$1997,B49) -> 1 | U49: =SUM(M49:R49) -> 0 | V49: =IF(B49="","",J49) -> 8
A50: 43 | B50: A.01.0774.003.P | C50: =IF(B50="","",IFERROR(IF(TRIM(MID(SUBSTITUTE(B50,".",REPT(" ",50)),51,50))="01","Masculino",IF(TRIM(MID(SUBSTITUTE(B50,".",REPT(" ",50)),51,50))="02","Feminino",IF(TRIM(MID(SUBSTITUTE(B50,".",REPT(" ",50)),51,50))="03","Outros","—"))),"—")) -> Masculino | D50: =IFERROR(INDEX(SKUs!$E$6:$E$1997,MATCH(B50,SKUs!$C$6:$C$1997,0)),"") -> CAMISETA | E50: =IFERROR(VLOOKUP(D50,Configurações!$N$5:$O$46,2,FALSE()),"OUTROS") -> VESTUÁRIO | F50: =IFERROR(INDEX(SKUs!$F$6:$F$1997,MATCH(B50,SKUs!$C$6:$C$1997,0)),"") -> CAMISETA COPA MASC. | G50: =IFERROR(INDEX(SKUs!$G$6:$G$1997,MATCH(B50,SKUs!$C$6:$C$1997,0)),"") -> BRANCA | H50: =IFERROR(INDEX(SKUs!$H$6:$H$1997,MATCH(B50,SKUs!$C$6:$C$1997,0)),"") -> P | I50: =IFERROR(INDEX(SKUs!#REF!,MATCH(B50,SKUs!$C$6:$C$1997,0)),"") | J50: =SUMIFS(SKUs!$I$6:$I$1997,SKUs!$C$6:$C$1997,B50) -> 0 | K50: =IFERROR(I50*J50,0) -> 0 | L50: =COUNTIF(SKUs!$C$6:$C$1997,B50) -> 2 | M50: 14 | U50: =SUM(M50:R50) -> 14 | V50: =IF(B50="","",J50) -> 0
A51: 44 | B51: A.01.0774.003.M | C51: =IF(B51="","",IFERROR(IF(TRIM(MID(SUBSTITUTE(B51,".",REPT(" ",50)),51,50))="01","Masculino",IF(TRIM(MID(SUBSTITUTE(B51,".",REPT(" ",50)),51,50))="02","Feminino",IF(TRIM(MID(SUBSTITUTE(B51,".",REPT(" ",50)),51,50))="03","Outros","—"))),"—")) -> Masculino | D51: =IFERROR(INDEX(SKUs!$E$6:$E$1997,MATCH(B51,SKUs!$C$6:$C$1997,0)),"") -> CAMISETA | E51: =IFERROR(VLOOKUP(D51,Configurações!$N$5:$O$46,2,FALSE()),"OUTROS") -> VESTUÁRIO | F51: =IFERROR(INDEX(SKUs!$F$6:$F$1997,MATCH(B51,SKUs!$C$6:$C$1997,0)),"") -> CAMISETA COPA MASC. | G51: =IFERROR(INDEX(SKUs!$G$6:$G$1997,MATCH(B51,SKUs!$C$6:$C$1997,0)),"") -> BRANCA | H51: =IFERROR(INDEX(SKUs!$H$6:$H$1997,MATCH(B51,SKUs!$C$6:$C$1997,0)),"") -> M | I51: =IFERROR(INDEX(SKUs!#REF!,MATCH(B51,SKUs!$C$6:$C$1997,0)),"") | J51: =SUMIFS(SKUs!$I$6:$I$1997,SKUs!$C$6:$C$1997,B51) -> 0 | K51: =IFERROR(I51*J51,0) -> 0 | L51: =COUNTIF(SKUs!$C$6:$C$1997,B51) -> 2 | M51: 15 | U51: =SUM(M51:R51) -> 15 | V51: =IF(B51="","",J51) -> 0
A52: 45 | B52: A.01.0774.003.G | C52: =IF(B52="","",IFERROR(IF(TRIM(MID(SUBSTITUTE(B52,".",REPT(" ",50)),51,50))="01","Masculino",IF(TRIM(MID(SUBSTITUTE(B52,".",REPT(" ",50)),51,50))="02","Feminino",IF(TRIM(MID(SUBSTITUTE(B52,".",REPT(" ",50)),51,50))="03","Outros","—"))),"—")) -> Masculino | D52: =IFERROR(INDEX(SKUs!$E$6:$E$1997,MATCH(B52,SKUs!$C$6:$C$1997,0)),"") -> CAMISETA | E52: =IFERROR(VLOOKUP(D52,Configurações!$N$5:$O$46,2,FALSE()),"OUTROS") -> VESTUÁRIO | F52: =IFERROR(INDEX(SKUs!$F$6:$F$1997,MATCH(B52,SKUs!$C$6:$C$1997,0)),"") -> CAMISETA COPA MASC. | G52: =IFERROR(INDEX(SKUs!$G$6:$G$1997,MATCH(B52,SKUs!$C$6:$C$1997,0)),"") -> BRANCA | H52: =IFERROR(INDEX(SKUs!$H$6:$H$1997,MATCH(B52,SKUs!$C$6:$C$1997,0)),"") -> G | I52: =IFERROR(INDEX(SKUs!#REF!,MATCH(B52,SKUs!$C$6:$C$1997,0)),"") | J52: =SUMIFS(SKUs!$I$6:$I$1997,SKUs!$C$6:$C$1997,B52) -> 0 | K52: =IFERROR(I52*J52,0) -> 0 | L52: =COUNTIF(SKUs!$C$6:$C$1997,B52) -> 2 | M52: 15 | U52: =SUM(M52:R52) -> 15 | V52: =IF(B52="","",J52) -> 0
A53: 46 | B53: A.01.0774.003.2G | C53: =IF(B53="","",IFERROR(IF(TRIM(MID(SUBSTITUTE(B53,".",REPT(" ",50)),51,50))="01","Masculino",IF(TRIM(MID(SUBSTITUTE(B53,".",REPT(" ",50)),51,50))="02","Feminino",IF(TRIM(MID(SUBSTITUTE(B53,".",REPT(" ",50)),51,50))="03","Outros","—"))),"—")) -> Masculino | D53: =IFERROR(INDEX(SKUs!$E$6:$E$1997,MATCH(B53,SKUs!$C$6:$C$1997,0)),"") -> CAMISETA | E53: =IFERROR(VLOOKUP(D53,Configurações!$N$5:$O$46,2,FALSE()),"OUTROS") -> VESTUÁRIO | F53: =IFERROR(INDEX(SKUs!$F$6:$F$1997,MATCH(B53,SKUs!$C$6:$C$1997,0)),"") -> CAMISETA COPA MASC. | G53: =IFERROR(INDEX(SKUs!$G$6:$G$1997,MATCH(B53,SKUs!$C$6:$C$1997,0)),"") -> BRANCA | H53: =IFERROR(INDEX(SKUs!$H$6:$H$1997,MATCH(B53,SKUs!$C$6:$C$1997,0)),"") -> GG | I53: =IFERROR(INDEX(SKUs!#REF!,MATCH(B53,SKUs!$C$6:$C$1997,0)),"") | J53: =SUMIFS(SKUs!$I$6:$I$1997,SKUs!$C$6:$C$1997,B53) -> 0 | K53: =IFERROR(I53*J53,0) -> 0 | L53: =COUNTIF(SKUs!$C$6:$C$1997,B53) -> 2 | M53: 15 | U53: =SUM(M53:R53) -> 15 | V53: =IF(B53="","",J53) -> 0
A54: 47 | B54: A.01.0774.003.3G | C54: =IF(B54="","",IFERROR(IF(TRIM(MID(SUBSTITUTE(B54,".",REPT(" ",50)),51,50))="01","Masculino",IF(TRIM(MID(SUBSTITUTE(B54,".",REPT(" ",50)),51,50))="02","Feminino",IF(TRIM(MID(SUBSTITUTE(B54,".",REPT(" ",50)),51,50))="03","Outros","—"))),"—")) -> Masculino | D54: =IFERROR(INDEX(SKUs!$E$6:$E$1997,MATCH(B54,SKUs!$C$6:$C$1997,0)),"") -> CAMISETA | E54: =IFERROR(VLOOKUP(D54,Configurações!$N$5:$O$46,2,FALSE()),"OUTROS") -> VESTUÁRIO | F54: =IFERROR(INDEX(SKUs!$F$6:$F$1997,MATCH(B54,SKUs!$C$6:$C$1997,0)),"") -> CAMISETA COPA MASC. | G54: =IFERROR(INDEX(SKUs!$G$6:$G$1997,MATCH(B54,SKUs!$C$6:$C$1997,0)),"") -> BRANCA | H54: =IFERROR(INDEX(SKUs!$H$6:$H$1997,MATCH(B54,SKUs!$C$6:$C$1997,0)),"") -> XG | I54: =IFERROR(INDEX(SKUs!#REF!,MATCH(B54,SKUs!$C$6:$C$1997,0)),"") | J54: =SUMIFS(SKUs!$I$6:$I$1997,SKUs!$C$6:$C$1997,B54) -> 0 | K54: =IFERROR(I54*J54,0) -> 0 | L54: =COUNTIF(SKUs!$C$6:$C$1997,B54) -> 2 | M54: 12 | U54: =SUM(M54:R54) -> 12 | V54: =IF(B54="","",J54) -> 0
A55: 48 | B55: A.01.0774.003.4G | C55: =IF(B55="","",IFERROR(IF(TRIM(MID(SUBSTITUTE(B55,".",REPT(" ",50)),51,50))="01","Masculino",IF(TRIM(MID(SUBSTITUTE(B55,".",REPT(" ",50)),51,50))="02","Feminino",IF(TRIM(MID(SUBSTITUTE(B55,".",REPT(" ",50)),51,50))="03","Outros","—"))),"—")) -> Masculino | D55: =IFERROR(INDEX(SKUs!$E$6:$E$1997,MATCH(B55,SKUs!$C$6:$C$1997,0)),"") -> CAMISETA | E55: =IFERROR(VLOOKUP(D55,Configurações!$N$5:$O$46,2,FALSE()),"OUTROS") -> VESTUÁRIO | F55: =IFERROR(INDEX(SKUs!$F$6:$F$1997,MATCH(B55,SKUs!$C$6:$C$1997,0)),"") -> CAMISETA COPA MASC. | G55: =IFERROR(INDEX(SKUs!$G$6:$G$1997,MATCH(B55,SKUs!$C$6:$C$1997,0)),"") -> BRANCA | H55: =IFERROR(INDEX(SKUs!$H$6:$H$1997,MATCH(B55,SKUs!$C$6:$C$1997,0)),"") -> 4G | I55: =IFERROR(INDEX(SKUs!#REF!,MATCH(B55,SKUs!$C$6:$C$1997,0)),"") | J55: =SUMIFS(SKUs!$I$6:$I$1997,SKUs!$C$6:$C$1997,B55) -> 0 | K55: =IFERROR(I55*J55,0) -> 0 | L55: =COUNTIF(SKUs!$C$6:$C$1997,B55) -> 2 | M55: 5 | U55: =SUM(M55:R55) -> 5 | V55: =IF(B55="","",J55) -> 0
A56: 49 | B56: A.01.0709.004.PP | C56: =IF(B56="","",IFERROR(IF(TRIM(MID(SUBSTITUTE(B56,".",REPT(" ",50)),51,50))="01","Masculino",IF(TRIM(MID(SUBSTITUTE(B56,".",REPT(" ",50)),51,50))="02","Feminino",IF(TRIM(MID(SUBSTITUTE(B56,".",REPT(" ",50)),51,50))="03","Outros","—"))),"—")) -> Masculino | D56: =IFERROR(INDEX(SKUs!$E$6:$E$1997,MATCH(B56,SKUs!$C$6:$C$1997,0)),"") -> POLO | E56: =IFERROR(VLOOKUP(D56,Configurações!$N$5:$O$46,2,FALSE()),"OUTROS") -> VESTUÁRIO | F56: =IFERROR(INDEX(SKUs!$F$6:$F$1997,MATCH(B56,SKUs!$C$6:$C$1997,0)),"") -> POLO PIQUET MASC. | G56: =IFERROR(INDEX(SKUs!$G$6:$G$1997,MATCH(B56,SKUs!$C$6:$C$1997,0)),"") -> CINZA | H56: =IFERROR(INDEX(SKUs!$H$6:$H$1997,MATCH(B56,SKUs!$C$6:$C$1997,0)),"") -> PP | I56: =IFERROR(INDEX(SKUs!#REF!,MATCH(B56,SKUs!$C$6:$C$1997,0)),"") | J56: =SUMIFS(SKUs!$I$6:$I$1997,SKUs!$C$6:$C$1997,B56) -> 0 | K56: =IFERROR(I56*J56,0) -> 0 | L56: =COUNTIF(SKUs!$C$6:$C$1997,B56) -> 3 | M56: 27 | U56: =SUM(M56:R56) -> 27 | V56: =IF(B56="","",J56) -> 0
A57: 50 | B57: A.01.0709.004.P | C57: =IF(B57="","",IFERROR(IF(TRIM(MID(SUBSTITUTE(B57,".",REPT(" ",50)),51,50))="01","Masculino",IF(TRIM(MID(SUBSTITUTE(B57,".",REPT(" ",50)),51,50))="02","Feminino",IF(TRIM(MID(SUBSTITUTE(B57,".",REPT(" ",50)),51,50))="03","Outros","—"))),"—")) -> Masculino | D57: =IFERROR(INDEX(SKUs!$E$6:$E$1997,MATCH(B57,SKUs!$C$6:$C$1997,0)),"") -> POLO | E57: =IFERROR(VLOOKUP(D57,Configurações!$N$5:$O$46,2,FALSE()),"OUTROS") -> VESTUÁRIO | F57: =IFERROR(INDEX(SKUs!$F$6:$F$1997,MATCH(B57,SKUs!$C$6:$C$1997,0)),"") -> POLO PIQUET MASC. | G57: =IFERROR(INDEX(SKUs!$G$6:$G$1997,MATCH(B57,SKUs!$C$6:$C$1997,0)),"") -> CINZA | H57: =IFERROR(INDEX(SKUs!$H$6:$H$1997,MATCH(B57,SKUs!$C$6:$C$1997,0)),"") -> P | I57: =IFERROR(INDEX(SKUs!#REF!,MATCH(B57,SKUs!$C$6:$C$1997,0)),"") | J57: =SUMIFS(SKUs!$I$6:$I$1997,SKUs!$C$6:$C$1997,B57) -> 56 | K57: =IFERROR(I57*J57,0) -> 0 | L57: =COUNTIF(SKUs!$C$6:$C$1997,B57) -> 2 | U57: =SUM(M57:R57) -> 0 | V57: =IF(B57="","",J57) -> 56
A58: 51 | B58: A.01.0709.004.M | C58: =IF(B58="","",IFERROR(IF(TRIM(MID(SUBSTITUTE(B58,".",REPT(" ",50)),51,50))="01","Masculino",IF(TRIM(MID(SUBSTITUTE(B58,".",REPT(" ",50)),51,50))="02","Feminino",IF(TRIM(MID(SUBSTITUTE(B58,".",REPT(" ",50)),51,50))="03","Outros","—"))),"—")) -> Masculino | D58: =IFERROR(INDEX(SKUs!$E$6:$E$1997,MATCH(B58,SKUs!$C$6:$C$1997,0)),"") -> POLO | E58: =IFERROR(VLOOKUP(D58,Configurações!$N$5:$O$46,2,FALSE()),"OUTROS") -> VESTUÁRIO | F58: =IFERROR(INDEX(SKUs!$F$6:$F$1997,MATCH(B58,SKUs!$C$6:$C$1997,0)),"") -> POLO PIQUET MASC. | G58: =IFERROR(INDEX(SKUs!$G$6:$G$1997,MATCH(B58,SKUs!$C$6:$C$1997,0)),"") -> CINZA | H58: =IFERROR(INDEX(SKUs!$H$6:$H$1997,MATCH(B58,SKUs!$C$6:$C$1997,0)),"") -> M | I58: =IFERROR(INDEX(SKUs!#REF!,MATCH(B58,SKUs!$C$6:$C$1997,0)),"") | J58: =SUMIFS(SKUs!$I$6:$I$1997,SKUs!$C$6:$C$1997,B58) -> 130 | K58: =IFERROR(I58*J58,0) -> 0 | L58: =COUNTIF(SKUs!$C$6:$C$1997,B58) -> 3 | U58: =SUM(M58:R58) -> 0 | V58: =IF(B58="","",J58) -> 130
A59: 52 | B59: A.01.0709.004.G | C59: =IF(B59="","",IFERROR(IF(TRIM(MID(SUBSTITUTE(B59,".",REPT(" ",50)),51,50))="01","Masculino",IF(TRIM(MID(SUBSTITUTE(B59,".",REPT(" ",50)),51,50))="02","Feminino",IF(TRIM(MID(SUBSTITUTE(B59,".",REPT(" ",50)),51,50))="03","Outros","—"))),"—")) -> Masculino | D59: =IFERROR(INDEX(SKUs!$E$6:$E$1997,MATCH(B59,SKUs!$C$6:$C$1997,0)),"") -> POLO | E59: =IFERROR(VLOOKUP(D59,Configurações!$N$5:$O$46,2,FALSE()),"OUTROS") -> VESTUÁRIO | F59: =IFERROR(INDEX(SKUs!$F$6:$F$1997,MATCH(B59,SKUs!$C$6:$C$1997,0)),"") -> POLO PIQUET MASC. | G59: =IFERROR(INDEX(SKUs!$G$6:$G$1997,MATCH(B59,SKUs!$C$6:$C$1997,0)),"") -> CINZA | H59: =IFERROR(INDEX(SKUs!$H$6:$H$1997,MATCH(B59,SKUs!$C$6:$C$1997,0)),"") -> G | I59: =IFERROR(INDEX(SKUs!#REF!,MATCH(B59,SKUs!$C$6:$C$1997,0)),"") | J59: =SUMIFS(SKUs!$I$6:$I$1997,SKUs!$C$6:$C$1997,B59) -> 79 | K59: =IFERROR(I59*J59,0) -> 0 | L59: =COUNTIF(SKUs!$C$6:$C$1997,B59) -> 3 | U59: =SUM(M59:R59) -> 0 | V59: =IF(B59="","",J59) -> 79
...

Sheet SKUs
A1: BTG PACTUAL · SKUs (OPERACIONAL) · 1 linha por caixa física
A5: CÓD. BTG | B5: ESTOQUE | C5: CÓD. CLIENTE | D5: GÊNERO | E5: CATEGORIA | F5: PRODUTO | G5: COR | H5: TAM | I5: ESTOQUE ATUAL | J5: ESTADO | K5: RUA | L5: PRATELEIRA | M5: CAIXA | N5: ENDEREÇO | P5: aux 1ªRuaPrat | Q5: aux 1ªRuaCaixa | R5: aux 1ªCaixa | T5: aux rankBusca
A6: BTG-001 | B6: Eventos | C6: A.01.0782.001.P | D6: =IF(C6="","",IFERROR(IF(TRIM(MID(SUBSTITUTE(C6,".",REPT(" ",50)),51,50))="01","Masculino",IF(TRIM(MID(SUBSTITUTE(C6,".",REPT(" ",50)),51,50))="02","Feminino",IF(TRIM(MID(SUBSTITUTE(C6,".",REPT(" ",50)),51,50))="03","Outros","—"))),"—")) -> Masculino | E6: POLO | F6: POLO COPA MASC. | G6: AZUL | H6: G | I6: =SUMIFS(Movimentações!$F$6:$F$4998,Movimentações!$C$6:$C$4998,A6,Movimentações!$M$6:$M$4998,M6) -> 0 | J6: ✅ Ótimo | K6: A | L6: 1 | M6: C-01 | N6: =IF(AND(K6="",L6="",M6=""),"⚠ sem endereço","Rua "&K6&IF(L6="",""," · Prat "&L6)&IF(M6="",""," · "&M6)) -> Rua A · Prat 1 · C-01 | P6: =IF(A6="","",IF(AND(K6<>"",L6<>""),IF(COUNTIFS($K$6:K6,K6,$L$6:L6,L6)=1,1,0),0)) -> 1 | Q6: =IF(A6="","",IF(AND(K6<>"",M6<>""),IF(COUNTIFS($K$6:K6,K6,$M$6:M6,M6)=1,1,0),0)) -> 1 | R6: =IF(A6="","",IF(M6<>"",IF(COUNTIF($M$6:M6,M6)=1,1,0),0)) -> 1 | T6: =IF(AND($M6<>"",$M6='Mapa do Galpão'!$C$20),COUNTIF($M$6:$M6,'Mapa do Galpão'!$C$20),"")
A7: BTG-002 | B7: Eventos | C7: A.01.0782.001.M | D7: =IF(C7="","",IFERROR(IF(TRIM(MID(SUBSTITUTE(C7,".",REPT(" ",50)),51,50))="01","Masculino",IF(TRIM(MID(SUBSTITUTE(C7,".",REPT(" ",50)),51,50))="02","Feminino",IF(TRIM(MID(SUBSTITUTE(C7,".",REPT(" ",50)),51,50))="03","Outros","—"))),"—")) -> Masculino | E7: POLO | F7: POLO COPA MASC. | G7: AZUL | H7: M | I7: =SUMIFS(Movimentações!$F$6:$F$4998,Movimentações!$C$6:$C$4998,A7,Movimentações!$M$6:$M$4998,M7) -> 0 | J7: ✅ Ótimo | K7: A | L7: 1 | M7: C-01 | N7: =IF(AND(K7="",L7="",M7=""),"⚠ sem endereço","Rua "&K7&IF(L7="",""," · Prat "&L7)&IF(M7="",""," · "&M7)) -> Rua A · Prat 1 · C-01 | P7: =IF(A7="","",IF(AND(K7<>"",L7<>""),IF(COUNTIFS($K$6:K7,K7,$L$6:L7,L7)=1,1,0),0)) -> 0 | Q7: =IF(A7="","",IF(AND(K7<>"",M7<>""),IF(COUNTIFS($K$6:K7,K7,$M$6:M7,M7)=1,1,0),0)) -> 0 | R7: =IF(A7="","",IF(M7<>"",IF(COUNTIF($M$6:M7,M7)=1,1,0),0)) -> 0 | T7: =IF(AND($M7<>"",$M7='Mapa do Galpão'!$C$20),COUNTIF($M$6:$M7,'Mapa do Galpão'!$C$20),"")
A8: BTG-003 | B8: Eventos | C8: A.01.0782.001.G | D8: =IF(C8="","",IFERROR(IF(TRIM(MID(SUBSTITUTE(C8,".",REPT(" ",50)),51,50))="01","Masculino",IF(TRIM(MID(SUBSTITUTE(C8,".",REPT(" ",50)),51,50))="02","Feminino",IF(TRIM(MID(SUBSTITUTE(C8,".",REPT(" ",50)),51,50))="03","Outros","—"))),"—")) -> Masculino | E8: POLO | F8: POLO COPA MASC. | G8: AZUL | H8: XG | I8: =SUMIFS(Movimentações!$F$6:$F$4998,Movimentações!$C$6:$C$4998,A8,Movimentações!$M$6:$M$4998,M8) -> 0 | J8: ✅ Ótimo | K8: A | L8: 1 | M8: C-01 | N8: =IF(AND(K8="",L8="",M8=""),"⚠ sem endereço","Rua "&K8&IF(L8="",""," · Prat "&L8)&IF(M8="",""," · "&M8)) -> Rua A · Prat 1 · C-01 | P8: =IF(A8="","",IF(AND(K8<>"",L8<>""),IF(COUNTIFS($K$6:K8,K8,$L$6:L8,L8)=1,1,0),0)) -> 0 | Q8: =IF(A8="","",IF(AND(K8<>"",M8<>""),IF(COUNTIFS($K$6:K8,K8,$M$6:M8,M8)=1,1,0),0)) -> 0 | R8: =IF(A8="","",IF(M8<>"",IF(COUNTIF($M$6:M8,M8)=1,1,0),0)) -> 0 | T8: =IF(AND($M8<>"",$M8='Mapa do Galpão'!$C$20),COUNTIF($M$6:$M8,'Mapa do Galpão'!$C$20),"")
A9: BTG-003 | B9: Eventos | C9: A.01.0782.001.G | D9: =IF(C9="","",IFERROR(IF(TRIM(MID(SUBSTITUTE(C9,".",REPT(" ",50)),51,50))="01","Masculino",IF(TRIM(MID(SUBSTITUTE(C9,".",REPT(" ",50)),51,50))="02","Feminino",IF(TRIM(MID(SUBSTITUTE(C9,".",REPT(" ",50)),51,50))="03","Outros","—"))),"—")) -> Masculino | E9: POLO | F9: POLO COPA MASC. | G9: AZUL | H9: XG | I9: =SUMIFS(Movimentações!$F$6:$F$4998,Movimentações!$C$6:$C$4998,A9,Movimentações!$M$6:$M$4998,M9) -> 0 | J9: ✅ Ótimo | K9: A | L9: 1 | M9: C-02 | N9: =IF(AND(K9="",L9="",M9=""),"⚠ sem endereço","Rua "&K9&IF(L9="",""," · Prat "&L9)&IF(M9="",""," · "&M9)) -> Rua A · Prat 1 · C-02 | P9: =IF(A9="","",IF(AND(K9<>"",L9<>""),IF(COUNTIFS($K$6:K9,K9,$L$6:L9,L9)=1,1,0),0)) -> 0 | Q9: =IF(A9="","",IF(AND(K9<>"",M9<>""),IF(COUNTIFS($K$6:K9,K9,$M$6:M9,M9)=1,1,0),0)) -> 1 | R9: =IF(A9="","",IF(M9<>"",IF(COUNTIF($M$6:M9,M9)=1,1,0),0)) -> 1 | T9: =IF(AND($M9<>"",$M9='Mapa do Galpão'!$C$20),COUNTIF($M$6:$M9,'Mapa do Galpão'!$C$20),"")
A10: BTG-004 | B10: Eventos | C10: A.01.0782.001.2G | D10: =IF(C10="","",IFERROR(IF(TRIM(MID(SUBSTITUTE(C10,".",REPT(" ",50)),51,50))="01","Masculino",IF(TRIM(MID(SUBSTITUTE(C10,".",REPT(" ",50)),51,50))="02","Feminino",IF(TRIM(MID(SUBSTITUTE(C10,".",REPT(" ",50)),51,50))="03","Outros","—"))),"—")) -> Masculino | E10: POLO | F10: POLO COPA MASC. | G10: AZUL | H10: P | I10: =SUMIFS(Movimentações!$F$6:$F$4998,Movimentações!$C$6:$C$4998,A10,Movimentações!$M$6:$M$4998,M10) -> 0 | J10: ✅ Ótimo | K10: A | L10: 1 | M10: C-01 | N10: =IF(AND(K10="",L10="",M10=""),"⚠ sem endereço","Rua "&K10&IF(L10="",""," · Prat "&L10)&IF(M10="",""," · "&M10)) -> Rua A · Prat 1 · C-01 | P10: =IF(A10="","",IF(AND(K10<>"",L10<>""),IF(COUNTIFS($K$6:K10,K10,$L$6:L10,L10)=1,1,0),0)) -> 0 | Q10: =IF(A10="","",IF(AND(K10<>"",M10<>""),IF(COUNTIFS($K$6:K10,K10,$M$6:M10,M10)=1,1,0),0)) -> 0 | R10: =IF(A10="","",IF(M10<>"",IF(COUNTIF($M$6:M10,M10)=1,1,0),0)) -> 0 | T10: =IF(AND($M10<>"",$M10='Mapa do Galpão'!$C$20),COUNTIF($M$6:$M10,'Mapa do Galpão'!$C$20),"")
A11: BTG-004 | B11: Eventos | C11: A.01.0782.001.2G | D11: =IF(C11="","",IFERROR(IF(TRIM(MID(SUBSTITUTE(C11,".",REPT(" ",50)),51,50))="01","Masculino",IF(TRIM(MID(SUBSTITUTE(C11,".",REPT(" ",50)),51,50))="02","Feminino",IF(TRIM(MID(SUBSTITUTE(C11,".",REPT(" ",50)),51,50))="03","Outros","—"))),"—")) -> Masculino | E11: POLO | F11: POLO COPA MASC. | G11: AZUL | H11: P | I11: =SUMIFS(Movimentações!$F$6:$F$4998,Movimentações!$C$6:$C$4998,A11,Movimentações!$M$6:$M$4998,M11) -> 0 | J11: ✅ Ótimo | K11: A | L11: 1 | M11: C-02 | N11: =IF(AND(K11="",L11="",M11=""),"⚠ sem endereço","Rua "&K11&IF(L11="",""," · Prat "&L11)&IF(M11="",""," · "&M11)) -> Rua A · Prat 1 · C-02 | P11: =IF(A11="","",IF(AND(K11<>"",L11<>""),IF(COUNTIFS($K$6:K11,K11,$L$6:L11,L11)=1,1,0),0)) -> 0 | Q11: =IF(A11="","",IF(AND(K11<>"",M11<>""),IF(COUNTIFS($K$6:K11,K11,$M$6:M11,M11)=1,1,0),0)) -> 0 | R11: =IF(A11="","",IF(M11<>"",IF(COUNTIF($M$6:M11,M11)=1,1,0),0)) -> 0 | T11: =IF(AND($M11<>"",$M11='Mapa do Galpão'!$C$20),COUNTIF($M$6:$M11,'Mapa do Galpão'!$C$20),"")
A12: BTG-005 | B12: Eventos | C12: A.01.0782.001.3G | D12: =IF(C12="","",IFERROR(IF(TRIM(MID(SUBSTITUTE(C12,".",REPT(" ",50)),51,50))="01","Masculino",IF(TRIM(MID(SUBSTITUTE(C12,".",REPT(" ",50)),51,50))="02","Feminino",IF(TRIM(MID(SUBSTITUTE(C12,".",REPT(" ",50)),51,50))="03","Outros","—"))),"—")) -> Masculino | E12: POLO | F12: POLO COPA MASC. | G12: AZUL | H12: GG | I12: =SUMIFS(Movimentações!$F$6:$F$4998,Movimentações!$C$6:$C$4998,A12,Movimentações!$M$6:$M$4998,M12) -> 0 | J12: ✅ Ótimo | K12: A | L12: 1 | M12: C-02 | N12: =IF(AND(K12="",L12="",M12=""),"⚠ sem endereço","Rua "&K12&IF(L12="",""," · Prat "&L12)&IF(M12="",""," · "&M12)) -> Rua A · Prat 1 · C-02 | P12: =IF(A12="","",IF(AND(K12<>"",L12<>""),IF(COUNTIFS($K$6:K12,K12,$L$6:L12,L12)=1,1,0),0)) -> 0 | Q12: =IF(A12="","",IF(AND(K12<>"",M12<>""),IF(COUNTIFS($K$6:K12,K12,$M$6:M12,M12)=1,1,0),0)) -> 0 | R12: =IF(A12="","",IF(M12<>"",IF(COUNTIF($M$6:M12,M12)=1,1,0),0)) -> 0 | T12: =IF(AND($M12<>"",$M12='Mapa do Galpão'!$C$20),COUNTIF($M$6:$M12,'Mapa do Galpão'!$C$20),"")
